Workbook

Sheet 01 Removing Trend and Season
A1: t | B1: year | C1: quarter | D1: gva | I1: indicators
A2: 2015-Q1 | B2: 2015 | C2: 1 | D2: 150816 | H2: quarter | I2: raw | J2: cleaned
A3: 2015-Q2 | B3: 2015 | C3: 2 | D3: 159663 | E3: =D3-D2 -> 8847 | F3: =E3-_xlfn.XLOOKUP(C3,$H$3:$H$6,$J$3:$J$6) -> 1363.5455 | H3: 1 | I3: =AVERAGEIF($C$3:$C$43,1,$E$3:$E$43) -> -3870.5 | J3: =I3-$I$8 -> -6578.3182
A4: 2015-Q3 | B4: 2015 | C4: 3 | D4: 155573 | E4: =D4-D3 -> -4090 | F4: =E4-_xlfn.XLOOKUP(C4,$H$3:$H$6,$J$3:$J$6) -> 2603.5182 | H4: 2 | I4: =AVERAGEIF($C$3:$C$43,2,$E$3:$E$43) -> 10191.273 | J4: =I4-$I$8 -> 7483.4545
A5: 2015-Q4 | B5: 2015 | C5: 4 | D5: 161574 | E5: =D5-D4 -> 6001 | F5: =E5-_xlfn.XLOOKUP(C5,$H$3:$H$6,$J$3:$J$6) -> 212.61818 | H5: 3 | I5: =AVERAGEIF($C$3:$C$43,3,$E$3:$E$43) -> -3985.7 | J5: =I5-$I$8 -> -6693.5182
A6: 2016-Q1 | B6: 2016 | C6: 1 | D6: 154922 | E6: =D6-D5 -> -6652 | F6: =E6-_xlfn.XLOOKUP(C6,$H$3:$H$6,$J$3:$J$6) -> -73.681818 | H6: 4 | I6: =AVERAGEIF($C$3:$C$43,4,$E$3:$E$43) -> 8496.2 | J6: =I6-$I$8 -> 5788.3818
A7: 2016-Q2 | B7: 2016 | C7: 2 | D7: 164049 | E7: =D7-D6 -> 9127 | F7: =E7-_xlfn.XLOOKUP(C7,$H$3:$H$6,$J$3:$J$6) -> 1643.5455
A8: 2016-Q3 | B8: 2016 | C8: 3 | D8: 159126 | E8: =D8-D7 -> -4923 | F8: =E8-_xlfn.XLOOKUP(C8,$H$3:$H$6,$J$3:$J$6) -> 1770.5182 | H8: average | I8: =AVERAGE(I3:I6) -> 2707.8182 | J8: =AVERAGE(J3:J6) -> 0
A9: 2016-Q4 | B9: 2016 | C9: 4 | D9: 166215 | E9: =D9-D8 -> 7089 | F9: =E9-_xlfn.XLOOKUP(C9,$H$3:$H$6,$J$3:$J$6) -> 1300.6182
A10: 2017-Q1 | B10: 2017 | C10: 1 | D10: 161419 | E10: =D10-D9 -> -4796 | F10: =E10-_xlfn.XLOOKUP(C10,$H$3:$H$6,$J$3:$J$6) -> 1782.3182
A11: 2017-Q2 | B11: 2017 | C11: 2 | D11: 171164 | E11: =D11-D10 -> 9745 | F11: =E11-_xlfn.XLOOKUP(C11,$H$3:$H$6,$J$3:$J$6) -> 2261.5455
A12: 2017-Q3 | B12: 2017 | C12: 3 | D12: 166103 | E12: =D12-D11 -> -5061 | F12: =E12-_xlfn.XLOOKUP(C12,$H$3:$H$6,$J$3:$J$6) -> 1632.5182
A13: 2017-Q4 | B13: 2017 | C13: 4 | D13: 173248 | E13: =D13-D12 -> 7145 | F13: =E13-_xlfn.XLOOKUP(C13,$H$3:$H$6,$J$3:$J$6) -> 1356.6182
A14: 2018-Q1 | B14: 2018 | C14: 1 | D14: 170056 | E14: =D14-D13 -> -3192 | F14: =E14-_xlfn.XLOOKUP(C14,$H$3:$H$6,$J$3:$J$6) -> 3386.3182
A15: 2018-Q2 | B15: 2018 | C15: 2 | D15: 179008 | E15: =D15-D14 -> 8952 | F15: =E15-_xlfn.XLOOKUP(C15,$H$3:$H$6,$J$3:$J$6) -> 1468.5455
A16: 2018-Q3 | B16: 2018 | C16: 3 | D16: 173652 | E16: =D16-D15 -> -5356 | F16: =E16-_xlfn.XLOOKUP(C16,$H$3:$H$6,$J$3:$J$6) -> 1337.5182
A17: 2018-Q4 | B17: 2018 | C17: 4 | D17: 180841 | E17: =D17-D16 -> 7189 | F17: =E17-_xlfn.XLOOKUP(C17,$H$3:$H$6,$J$3:$J$6) -> 1400.6182
A18: 2019-Q1 | B18: 2019 | C18: 1 | D18: 178780 | E18: =D18-D17 -> -2061 | F18: =E18-_xlfn.XLOOKUP(C18,$H$3:$H$6,$J$3:$J$6) -> 4517.3182
A19: 2019-Q2 | B19: 2019 | C19: 2 | D19: 188735 | E19: =D19-D18 -> 9955 | F19: =E19-_xlfn.XLOOKUP(C19,$H$3:$H$6,$J$3:$J$6) -> 2471.5455
A20: 2019-Q3 | B20: 2019 | C20: 3 | D20: 182497 | E20: =D20-D19 -> -6238 | F20: =E20-_xlfn.XLOOKUP(C20,$H$3:$H$6,$J$3:$J$6) -> 455.51818
... A43: 2025-Q2 | B43: 2025 | C43: 2 | D43: 269320 | E43: =D43-D42 -> 15085 | F43: =E43-_xlfn.XLOOKUP(C43,$H$3:$H$6,$J$3:$J$6) -> 7601.5455

Sheet 02 Constant Prices
A1: t | B1: year | C1: quarter | D1: gvaConst2020 | E1: chainIndex | F1: gvaConst2020InConst2016 | G1: gvaConst2020InConst2024
A2: 2015-Q1 | B2: 2015 | C2: 1 | D2: 166342.2 | F2: =F3/E3 -> 152367.13 | G2: =G3/E3 -> 203587.31 | J2: Netherlands GVA in current prices in 2016 | K2: =SUM('01 Removing Trend and Season'!D6:D9) -> 644312
A3: 2015-Q2 | B3: 2015 | C3: 2 | D3: 176327.2 | E3: =D3/D2 -> 1.0600269 | F3: =F4/E4 -> 161513.25 | G3: =G4/E4 -> 215808.02 | K3: =SUM(F6:F9)-K2 -> 0
A4: 2015-Q3 | B4: 2015 | C4: 3 | D4: 169955.9 | E4: =D4/D3 -> 0.96386661 | F4: =F5/E5 -> 155677.23 | G4: =G5/E5 -> 208010.14
A5: 2015-Q4 | B5: 2015 | C5: 4 | D5: 175336.9 | E5: =D5/D4 -> 1.0316612 | F5: =F6/E6 -> 160606.15 | G5: =G6/E6 -> 214595.98
A6: 2016-Q1 | B6: 2016 | C6: 1 | D6: 169865.6 | E6: =D6/D5 -> 0.9687955 | F6: 155594.52 | G6: =G7/E7 -> 207899.62
A7: 2016-Q2 | B7: 2016 | C7: 2 | D7: 180668.9 | E7: =D7/D6 -> 1.0635991 | F7: =F6*E7 -> 165490.19 | G7: =G8/E8 -> 221121.85 | J7: Netherlands GVA in current prices in 2024 | K7: =SUM('01 Removing Trend and Season'!D38:D41) -> 1007338
A8: 2016-Q3 | B8: 2016 | C8: 3 | D8: 173693.6 | E8: =D8/D7 -> 0.96139181 | F8: =F7*E8 -> 159100.91 | G8: =G9/E9 -> 212584.74 | K8: =SUM(G38:G41)-K7 -> 0.38126828
A9: 2016-Q4 | B9: 2016 | C9: 4 | D9: 179180 | E9: =D9/D8 -> 1.0315867 | F9: =F8*E9 -> 164126.38 | G9: =G10/E10 -> 219299.58
A10: 2017-Q1 | B10: 2017 | C10: 1 | D10: 175078 | E10: =D10/D9 -> 0.97710682 | F10: =F9*E10 -> 160369 | G10: =G11/E11 -> 214279.11
A11: 2017-Q2 | B11: 2017 | C11: 2 | D11: 185815.2 | E11: =D11/D10 -> 1.0613281 | F11: =F10*E11 -> 170204.13 | G11: =G12/E12 -> 227420.44
A12: 2017-Q3 | B12: 2017 | C12: 3 | D12: 178391.6 | E12: =D12/D11 -> 0.96004848 | F12: =F11*E12 -> 163404.22 | G12: =G13/E13 -> 218334.65
A13: 2017-Q4 | B13: 2017 | C13: 4 | D13: 183728.6 | E13: =D13/D12 -> 1.0299173 | F13: =F12*E13 -> 168292.83 | G13: =G14/E14 -> 224866.64
A14: 2018-Q1 | B14: 2018 | C14: 1 | D14: 179164.1 | E14: =D14/D13 -> 0.97515629 | F14: =F13*E14 -> 164111.81 | G14: =G15/E15 -> 219280.12
A15: 2018-Q2 | B15: 2018 | C15: 2 | D15: 190645.2 | E15: =D15/D14 -> 1.0640815 | F15: =F14*E15 -> 174628.34 | G15: =G16/E16 -> 233331.91
A16: 2018-Q3 | B16: 2018 | C16: 3 | D16: 182038.1 | E16: =D16/D15 -> 0.95485278 | F16: =F15*E16 -> 166744.36 | G16: =G17/E17 -> 222797.63
A17: 2018-Q4 | B17: 2018 | C17: 4 | D17: 187167.2 | E17: =D17/D16 -> 1.028176 | F17: =F16*E17 -> 171442.54 | G17: =G18/E18 -> 229075.17
A18: 2019-Q1 | B18: 2019 | C18: 1 | D18: 183519.5 | E18: =D18/D17 -> 0.98051101 | F18: =F17*E18 -> 168101.3 | G18: =G19/E19 -> 224610.72
A19: 2019-Q2 | B19: 2019 | C19: 2 | D19: 194996.4 | E19: =D19/D18 -> 1.0625378 | F19: =F18*E19 -> 178613.98 | G19: =G20/E20 -> 238657.37
A20: 2019-Q3 | B20: 2019 | C20: 3 | D20: 186582.5 | E20: =D20/D19 -> 0.956851 | F20: =F19*E20 -> 170906.97 | G20: =G21/E21 -> 228359.55
... A37: 2023-Q4 | B37: 2023 | C37: 4 | D37: 207795 | E37: =D37/D36 -> 1.0451445 | F37: =F36*E37 -> 190337.32 | G37: =G38/E38 -> 254321.67
A38: 2024-Q1 | B38: 2024 | C38: 1 | D38: 197194.9 | E38: =D38/D37 -> 0.9489877 | F38: =F37*E38 -> 180627.78 | G38: 241348.13
A39: 2024-Q2 | B39: 2024 | C39: 2 | D39: 211997.6 | E39: =D39/D38 -> 1.0750663 | F39: =F38*E39 -> 194186.84 | G39: =G38*E39 -> 259465.25
A40: 2024-Q3 | B40: 2024 | C40: 3 | D40: 202171.4 | E40: =D40/D39 -> 0.95364948 | F40: =F39*E40 -> 185186.18 | G40: =G39*E40 -> 247438.9
A41: 2024-Q4 | B41: 2024 | C41: 4 | D41: 211687.8 | E41: =D41/D40 -> 1.047071 | F41: =F40*E41 -> 193903.07 | G41: =G40*E41 -> 259086.09
A42: 2025-Q1 | B42: 2025 | C42: 1 | D42: 201634.6 | E42: =D42/D41 -> 0.95250931 | F42: =F41*E42 -> 184694.48 | G42: =G41*E42 -> 246781.91
A43: 2025-Q2 | B43: 2025 | C43: 2 | D43: 215735.1 | E43: =D43/D42 -> 1.069931 | F43: =F42*E43 -> 197610.34 | G43: =G42*E43 -> 264039.61

Sheet 02 GVA Const 2020 in Const 2016
A1: t | B1: year | C1: quarter | D1: gva | I1: indicators
A2: 2015-Q1 | B2: 2015 | C2: 1 | D2: 152367.13 | H2: quarter | I2: raw | J2: cleaned
A3: 2015-Q2 | B3: 2015 | C3: 2 | D3: 161513.25 | E3: =D3-D2 -> 9146.1206 | F3: =E3-_xlfn.XLOOKUP(C3,$H$3:$H$6,$J$3:$J$6) -> -356.62709 | H3: 1 | I3: =AVERAGEIF($C$3:$C$43,1,$E$3:$E$43) -> -6427.7763 | J3: =I3-$I$8 -> -7299.4948
A4: 2015-Q3 | B4: 2015 | C4: 3 | D4: 155677.23 | E4: =D4-D3 -> -5836.0219 | F4: =E4-_xlfn.XLOOKUP(C4,$H$3:$H$6,$J$3:$J$6) -> 1646.4045 | H4: 2 | I4: =AVERAGEIF($C$3:$C$43,2,$E$3:$E$43) -> 10374.466 | J4: =I4-$I$8 -> 9502.7477
A5: 2015-Q4 | B5: 2015 | C5: 4 | D5: 160606.15 | E5: =D5-D4 -> 4928.9209 | F5: =E5-_xlfn.XLOOKUP(C5,$H$3:$H$6,$J$3:$J$6) -> -350.25266 | H5: 3 | I5: =AVERAGEIF($C$3:$C$43,3,$E$3:$E$43) -> -6610.7079 | J5: =I5-$I$8 -> -7482.4264
A6: 2016-Q1 | B6: 2016 | C6: 1 | D6: 155594.52 | E6: =D6-D5 -> -5011.6344 | F6: =E6-_xlfn.XLOOKUP(C6,$H$3:$H$6,$J$3:$J$6) -> 2287.8604 | H6: 4 | I6: =AVERAGEIF($C$3:$C$43,4,$E$3:$E$43) -> 6150.8921 | J6: =I6-$I$8 -> 5279.1735
A7: 2016-Q2 | B7: 2016 | C7: 2 | D7: 165490.19 | E7: =D7-D6 -> 9895.672 | F7: =E7-_xlfn.XLOOKUP(C7,$H$3:$H$6,$J$3:$J$6) -> 392.92429
A8: 2016-Q3 | B8: 2016 | C8: 3 | D8: 159100.91 | E8: =D8-D7 -> -6389.2774 | F8: =E8-_xlfn.XLOOKUP(C8,$H$3:$H$6,$J$3:$J$6) -> 1093.149 | H8: average | I8: =AVERAGE(I3:I6) -> 871.71852 | J8: =AVERAGE(J3:J6) -> 0 | L8: The impact of inflation is reduced!
A9: 2016-Q4 | B9: 2016 | C9: 4 | D9: 164126.38 | E9: =D9-D8 -> 5025.4658 | F9: =E9-_xlfn.XLOOKUP(C9,$H$3:$H$6,$J$3:$J$6) -> -253.70773
A10: 2017-Q1 | B10: 2017 | C10: 1 | D10: 160369 | E10: =D10-D9 -> -3757.3747 | F10: =E10-_xlfn.XLOOKUP(C10,$H$3:$H$6,$J$3:$J$6) -> 3542.1201
A11: 2017-Q2 | B11: 2017 | C11: 2 | D11: 170204.13 | E11: =D11-D10 -> 9835.1253 | F11: =E11-_xlfn.XLOOKUP(C11,$H$3:$H$6,$J$3:$J$6) -> 332.37761
A12: 2017-Q3 | B12: 2017 | C12: 3 | D12: 163404.22 | E12: =D12-D11 -> -6799.914 | F12: =E12-_xlfn.XLOOKUP(C12,$H$3:$H$6,$J$3:$J$6) -> 682.51244
A13: 2017-Q4 | B13: 2017 | C13: 4 | D13: 168292.83 | E13: =D13-D12 -> 4888.6175 | F13: =E13-_xlfn.XLOOKUP(C13,$H$3:$H$6,$J$3:$J$6) -> -390.55605
A14: 2018-Q1 | B14: 2018 | C14: 1 | D14: 164111.81 | E14: =D14-D13 -> -4181.0183 | F14: =E14-_xlfn.XLOOKUP(C14,$H$3:$H$6,$J$3:$J$6) -> 3118.4766
A15: 2018-Q2 | B15: 2018 | C15: 2 | D15: 174628.34 | E15: =D15-D14 -> 10516.527 | F15: =E15-_xlfn.XLOOKUP(C15,$H$3:$H$6,$J$3:$J$6) -> 1013.7796
A16: 2018-Q3 | B16: 2018 | C16: 3 | D16: 166744.36 | E16: =D16-D15 -> -7883.9834 | F16: =E16-_xlfn.XLOOKUP(C16,$H$3:$H$6,$J$3:$J$6) -> -401.55704
A17: 2018-Q4 | B17: 2018 | C17: 4 | D17: 171442.54 | E17: =D17-D16 -> 4698.184 | F17: =E17-_xlfn.XLOOKUP(C17,$H$3:$H$6,$J$3:$J$6) -> -580.98954
A18: 2019-Q1 | B18: 2019 | C18: 1 | D18: 168101.3 | E18: =D18-D17 -> -3341.2423 | F18: =E18-_xlfn.XLOOKUP(C18,$H$3:$H$6,$J$3:$J$6) -> 3958.2526
A19: 2019-Q2 | B19: 2019 | C19: 2 | D19: 178613.98 | E19: =D19-D18 -> 10512.68 | F19: =E19-_xlfn.XLOOKUP(C19,$H$3:$H$6,$J$3:$J$6) -> 1009.9325
A20: 2019-Q3 | B20: 2019 | C20: 3 | D20: 170906.97 | E20: =D20-D19 -> -7707.0149 | F20: =E20-_xlfn.XLOOKUP(C20,$H$3:$H$6,$J$3:$J$6) -> -224.58854
... A43: 2025-Q2 | B43: 2025 | C43: 2 | D43: 197610.34 | E43: =D43-D42 -> 12915.861 | F43: =E43-_xlfn.XLOOKUP(C43,$H$3:$H$6,$J$3:$J$6) -> 3413.1135

Sheet 02 GVA Const 2020 in Const 2024
A1: t | B1: year | C1: quarter | D1: gva | I1: indicators
A2: 2015-Q1 | B2: 2015 | C2: 1 | D2: 203587.31 | H2: quarter | I2: raw | J2: cleaned
A3: 2015-Q2 | B3: 2015 | C3: 2 | D3: 215808.02 | E3: =D3-D2 -> 12220.707 | F3: =E3-_xlfn.XLOOKUP(C3,$H$3:$H$6,$J$3:$J$6) -> -476.51189 | H3: 1 | I3: =AVERAGEIF($C$3:$C$43,1,$E$3:$E$43) -> -8588.5563 | J3: =I3-$I$8 -> -9753.3142
A4: 2015-Q3 | B4: 2015 | C4: 3 | D4: 208010.14 | E4: =D4-D3 -> -7797.8759 | F4: =E4-_xlfn.XLOOKUP(C4,$H$3:$H$6,$J$3:$J$6) -> 2199.8647 | H4: 2 | I4: =AVERAGEIF($C$3:$C$43,2,$E$3:$E$43) -> 13861.977 | J4: =I4-$I$8 -> 12697.219
A5: 2015-Q4 | B5: 2015 | C5: 4 | D5: 214595.98 | E5: =D5-D4 -> 6585.8412 | F5: =E5-_xlfn.XLOOKUP(C5,$H$3:$H$6,$J$3:$J$6) -> -467.99461 | H5: 3 | I5: =AVERAGEIF($C$3:$C$43,3,$E$3:$E$43) -> -8832.9827 | J5: =I5-$I$8 -> -9997.7406
A6: 2016-Q1 | B6: 2016 | C6: 1 | D6: 207899.62 | E6: =D6-D5 -> -6696.36 | F6: =E6-_xlfn.XLOOKUP(C6,$H$3:$H$6,$J$3:$J$6) -> 3056.9542 | H6: 4 | I6: =AVERAGEIF($C$3:$C$43,4,$E$3:$E$43) -> 8218.5938 | J6: =I6-$I$8 -> 7053.8359
A7: 2016-Q2 | B7: 2016 | C7: 2 | D7: 221121.85 | E7: =D7-D6 -> 13222.23 | F7: =E7-_xlfn.XLOOKUP(C7,$H$3:$H$6,$J$3:$J$6) -> 525.01086
A8: 2016-Q3 | B8: 2016 | C8: 3 | D8: 212584.74 | E8: =D8-D7 -> -8537.1155 | F8: =E8-_xlfn.XLOOKUP(C8,$H$3:$H$6,$J$3:$J$6) -> 1460.6251 | H8: average | I8: =AVERAGE(I3:I6) -> 1164.7579 | J8: =AVERAGE(J3:J6) -> 0 | L8: The impact of inflation is reduced!
A9: 2016-Q4 | B9: 2016 | C9: 4 | D9: 219299.58 | E9: =D9-D8 -> 6714.841 | F9: =E9-_xlfn.XLOOKUP(C9,$H$3:$H$6,$J$3:$J$6) -> -338.99486
A10: 2017-Q1 | B10: 2017 | C10: 1 | D10: 214279.11 | E10: =D10-D9 -> -5020.4647 | F10: =E10-_xlfn.XLOOKUP(C10,$H$3:$H$6,$J$3:$J$6) -> 4732.8495
A11: 2017-Q2 | B11: 2017 | C11: 2 | D11: 227420.44 | E11: =D11-D10 -> 13141.33 | F11: =E11-_xlfn.XLOOKUP(C11,$H$3:$H$6,$J$3:$J$6) -> 444.11063
A12: 2017-Q3 | B12: 2017 | C12: 3 | D12: 218334.65 | E12: =D12-D11 -> -9085.7928 | F12: =E12-_xlfn.XLOOKUP(C12,$H$3:$H$6,$J$3:$J$6) -> 911.9478
A13: 2017-Q4 | B13: 2017 | C13: 4 | D13: 224866.64 | E13: =D13-D12 -> 6531.9894 | F13: =E13-_xlfn.XLOOKUP(C13,$H$3:$H$6,$J$3:$J$6) -> -521.8465
A14: 2018-Q1 | B14: 2018 | C14: 1 | D14: 219280.12 | E14: =D14-D13 -> -5586.5215 | F14: =E14-_xlfn.XLOOKUP(C14,$H$3:$H$6,$J$3:$J$6) -> 4166.7927
A15: 2018-Q2 | B15: 2018 | C15: 2 | D15: 233331.91 | E15: =D15-D14 -> 14051.794 | F15: =E15-_xlfn.XLOOKUP(C15,$H$3:$H$6,$J$3:$J$6) -> 1354.5747
A16: 2018-Q3 | B16: 2018 | C16: 3 | D16: 222797.63 | E16: =D16-D15 -> -10534.286 | F16: =E16-_xlfn.XLOOKUP(C16,$H$3:$H$6,$J$3:$J$6) -> -536.54562
A17: 2018-Q4 | B17: 2018 | C17: 4 | D17: 229075.17 | E17: =D17-D16 -> 6277.5392 | F17: =E17-_xlfn.XLOOKUP(C17,$H$3:$H$6,$J$3:$J$6) -> -776.29668
A18: 2019-Q1 | B18: 2019 | C18: 1 | D18: 224610.72 | E18: =D18-D17 -> -4464.444 | F18: =E18-_xlfn.XLOOKUP(C18,$H$3:$H$6,$J$3:$J$6) -> 5288.8702
A19: 2019-Q2 | B19: 2019 | C19: 2 | D19: 238657.37 | E19: =D19-D18 -> 14046.653 | F19: =E19-_xlfn.XLOOKUP(C19,$H$3:$H$6,$J$3:$J$6) -> 1349.4343
A20: 2019-Q3 | B20: 2019 | C20: 3 | D20: 228359.55 | E20: =D20-D19 -> -10297.827 | F20: =E20-_xlfn.XLOOKUP(C20,$H$3:$H$6,$J$3:$J$6) -> -300.08687
... A43: 2025-Q2 | B43: 2025 | C43: 2 | D43: 264039.61 | E43: =D43-D42 -> 17257.695 | F43: =E43-_xlfn.XLOOKUP(C43,$H$3:$H$6,$J$3:$J$6) -> 4560.4756

Sheet 03 Linear Trend
A1: GVA | C1: time
A2: 150816 | C2: 1 | E2: =A2 -> 150816 | G2: 1 | H2: =C2 -> 1 | J2: =$Q$10+$Q$11*H2 -> 141613.78 | L2: =(J2-A2)^2 -> 84680778 | O2: {=TRANSPOSE(G2:H43)} -> 1 | P2: 1 | Q2: 1 | R2: 1 | S2: 1 | T2: 1 | U2: 1 | V2: 1 | W2: 1 | X2: 1 | Y2: 1 | Z2: 1 | AA2: 1 | AB2: 1 | AC2: 1 | AD2: 1 | AE2: 1 | AF2: 1 | AG2: 1 | AH2: 1 | AI2: 1 | AJ2: 1 | AK2: 1 | AL2: 1 | AM2: 1 | AN2: 1 | AO2: 1 | AP2: 1 | AQ2: 1 | AR2: 1 | AS2: 1 | AT2: 1 | AU2: 1 | AV2: 1 | AW2: 1 | AX2: 1 | AY2: 1 | AZ2: 1 | BA2: 1 | BB2: 1 | BC2: 1 | BD2: 1
A3: 159663 | C3: 2 | E3: =A3 -> 159663 | G3: 1 | H3: =C3 -> 2 | J3: =$Q$10+$Q$11*H3 -> 144309.38 | L3: =(J3-A3)^2 -> 2.3573376e+08 | O3: 1 | P3: 2 | Q3: 3 | R3: 4 | S3: 5 | T3: 6 | U3: 7 | V3: 8 | W3: 9 | X3: 10 | Y3: 11 | Z3: 12 | AA3: 13 | AB3: 14 | AC3: 15 | AD3: 16 | AE3: 17 | AF3: 18 | AG3: 19 | AH3: 20 | AI3: 21 | AJ3: 22 | AK3: 23 | AL3: 24 | AM3: 25 | AN3: 26 | AO3: 27 | AP3: 28 | AQ3: 29 | AR3: 30 | AS3: 31 | AT3: 32 | AU3: 33 | AV3: 34 | AW3: 35 | AX3: 36 | AY3: 37 | AZ3: 38 | BA3: 39 | BB3: 40 | BC3: 41 | BD3: 42
A4: 155573 | C4: 3 | E4: =A4 -> 155573 | G4: 1 | H4: =C4 -> 3 | J4: =$Q$10+$Q$11*H4 -> 147004.97 | L4: =(J4-A4)^2 -> 73411157
A5: 161574 | C5: 4 | E5: =A5 -> 161574 | G5: 1 | H5: =C5 -> 4 | J5: =$Q$10+$Q$11*H5 -> 149700.56 | L5: =(J5-A5)^2 -> 1.4097855e+08
A6: 154922 | C6: 5 | E6: =A6 -> 154922 | G6: 1 | H6: =C6 -> 5 | J6: =$Q$10+$Q$11*H6 -> 152396.15 | L6: =(J6-A6)^2 -> 6379899.5 | O6: {=MMULT(_xlfn.ANCHORARRAY(O2),G2:H43)} -> 42 | P6: 903 | R6: {=MINVERSE(_xlfn.ANCHORARRAY(O6))} -> 0.098722416 | S6: -0.0034843206
A7: 164049 | C7: 6 | E7: =A7 -> 164049 | G7: 1 | H7: =C7 -> 6 | J7: =$Q$10+$Q$11*H7 -> 155091.75 | L7: =(J7-A7)^2 -> 80232397 | O7: 903 | P7: 25585 | R7: -0.0034843206 | S7: 0.00016206142
A8: 159126 | C8: 7 | E8: =A8 -> 159126 | G8: 1 | H8: =C8 -> 7 | J8: =$Q$10+$Q$11*H8 -> 157787.34 | L8: =(J8-A8)^2 -> 1792014.5
A9: 166215 | C9: 8 | E9: =A9 -> 166215 | G9: 1 | H9: =C9 -> 8 | J9: =$Q$10+$Q$11*H9 -> 160482.93 | L9: =(J9-A9)^2 -> 32856615
A10: 161419 | C10: 9 | E10: =A10 -> 161419 | G10: 1 | H10: =C10 -> 9 | J10: =$Q$10+$Q$11*H10 -> 163178.52 | L10: =(J10-A10)^2 -> 3095922.5 | O10: {=MMULT(_xlfn.ANCHORARRAY(O2),E2:E43)} -> 8268684 | Q10: {=MMULT(_xlfn.ANCHORARRAY(R6),_xlfn.ANCHORARRAY(O10))} -> 138918.19
A11: 171164 | C11: 10 | E11: =A11 -> 171164 | G11: 1 | H11: =C11 -> 10 | J11: =$Q$10+$Q$11*H11 -> 165874.12 | L11: =(J11-A11)^2 -> 27982875 | O11: 194409859 | Q11: 2695.5924
A12: 166103 | C12: 11 | E12: =A12 -> 166103 | G12: 1 | H12: =C12 -> 11 | J12: =$Q$10+$Q$11*H12 -> 168569.71 | L12: =(J12-A12)^2 -> 6084649.4
A13: 173248 | C13: 12 | E13: =A13 -> 173248 | G13: 1 | H13: =C13 -> 12 | J13: =$Q$10+$Q$11*H13 -> 171265.3 | L13: =(J13-A13)^2 -> 3931096.8
A14: 170056 | C14: 13 | E14: =A14 -> 170056 | G14: 1 | H14: =C14 -> 13 | J14: =$Q$10+$Q$11*H14 -> 173960.89 | L14: =(J14-A14)^2 -> 15248190
A15: 179008 | C15: 14 | E15: =A15 -> 179008 | G15: 1 | H15: =C15 -> 14 | J15: =$Q$10+$Q$11*H15 -> 176656.49 | L15: =(J15-A15)^2 -> 5529620.7
A16: 173652 | C16: 15 | E16: =A16 -> 173652 | G16: 1 | H16: =C16 -> 15 | J16: =$Q$10+$Q$11*H16 -> 179352.08 | L16: =(J16-A16)^2 -> 32490888 | O16: =SUM(L2:L43) -> 4.0364354e+09 | Q16: =O16/(COUNT(J2:J43)-2) -> 1.0091089e+08
A17: 180841 | C17: 16 | E17: =A17 -> 180841 | G17: 1 | H17: =C17 -> 16 | J17: =$Q$10+$Q$11*H17 -> 182047.67 | L17: =(J17-A17)^2 -> 1456053.2
A18: 178780 | C18: 17 | E18: =A18 -> 178780 | G18: 1 | H18: =C18 -> 17 | J18: =$Q$10+$Q$11*H18 -> 184743.26 | L18: =(J18-A18)^2 -> 35560502
A19: 188735 | C19: 18 | E19: =A19 -> 188735 | G19: 1 | H19: =C19 -> 18 | J19: =$Q$10+$Q$11*H19 -> 187438.86 | L19: =(J19-A19)^2 -> 1679991.6
A20: 182497 | C20: 19 | E20: =A20 -> 182497 | G20: 1 | H20: =C20 -> 19 | J20: =$Q$10+$Q$11*H20 -> 190134.45 | L20: =(J20-A20)^2 -> 58330605
A21: 189496 | C21: 20 | E21: =A21 -> 189496 | G21: 1 | H21: =C21 -> 20 | J21: =$Q$10+$Q$11*H21 -> 192830.04 | L21: =(J21-A21)^2 -> 11115822 | O21: =$Q$16*R6 -> 9962166.4 | P21: =$Q$16*S6 -> -351605.87
A22: 182537 | C22: 21 | E22: =A22 -> 182537 | G22: 1 | H22: =C22 -> 21 | J22: =$Q$10+$Q$11*H22 -> 195525.63 | L22: =(J22-A22)^2 -> 1.6870457e+08 | O22: =$Q$16*R7 -> -351605.87 | P22: =$Q$16*S7 -> 16353.762
A23: 175396 | C23: 22 | E23: =A23 -> 175396 | G23: 1 | H23: =C23 -> 22 | J23: =$Q$10+$Q$11*H23 -> 198221.22 | L23: =(J23-A23)^2 -> 5.2099089e+08
A24: 179815 | C24: 23 | E24: =A24 -> 179815 | G24: 1 | H24: =C24 -> 23 | J24: =$Q$10+$Q$11*H24 -> 200916.82 | L24: =(J24-A24)^2 -> 4.4528669e+08
A25: 188401 | C25: 24 | E25: =A25 -> 188401 | G25: 1 | H25: =C25 -> 24 | J25: =$Q$10+$Q$11*H25 -> 203612.41 | L25: =(J25-A25)^2 -> 2.3138698e+08
A26: 183940 | C26: 25 | E26: =A26 -> 183940 | G26: 1 | H26: =C26 -> 25 | J26: =$Q$10+$Q$11*H26 -> 206308 | L26: =(J26-A26)^2 -> 5.0032751e+08 | Y26: If the p-value is less than 0.1, we conclude that the parameter is statistically significant.
A27: 201433 | C27: 26 | E27: =A27 -> 201433 | G27: 1 | H27: =C27 -> 26 | J27: =$Q$10+$Q$11*H27 -> 209003.59 | L27: =(J27-A27)^2 -> 57313900 | O27: =SQRT(O21) -> 3156.29 | P27: =SQRT(P21) -> #NUM! | S27: 0 | T27: =Q10 -> 138918.19 | U27: =O27 -> 3156.29 | V27: =T27/U27 -> 44.013127 | W27: =_xlfn.T.DIST.2T(V27,40) -> 1.6703398e-35 | Y27: Statistically significant
A28: 198942 | C28: 27 | E28: =A28 -> 198942 | G28: 1 | H28: =C28 -> 27 | J28: =$Q$10+$Q$11*H28 -> 211699.19 | L28: =(J28-A28)^2 -> 1.6274582e+08 | O28: =SQRT(O22) -> #NUM! | P28: =SQRT(P22) -> 127.88183 | S28: 1 | T28: =Q11 -> 2695.5924 | U28: =P28 -> 127.88183 | V28: =T28/U28 -> 21.078776 | W28: =_xlfn.T.DIST.2T(V28,40) -> 2.8486105e-23 | Y28: Statistically significant
A29: 207415 | C29: 28 | E29: =A29 -> 207415 | G29: 1 | H29: =C29 -> 28 | J29: =$Q$10+$Q$11*H29 -> 214394.78 | L29: =(J29-A29)^2 -> 48717319
A30: 209214 | C30: 29 | E30: =A30 -> 209214 | G30: 1 | H30: =C30 -> 29 | J30: =$Q$10+$Q$11*H30 -> 217090.37 | L30: =(J30-A30)^2 -> 62037231
A31: 224204 | C31: 30 | E31: =A31 -> 224204 | G31: 1 | H31: =C31 -> 30 | J31: =$Q$10+$Q$11*H31 -> 219785.96 | L31: =(J31-A31)^2 -> 19519041 | U31: Linear model formula
A32: 221953 | C32: 31 | E32: =A32 -> 221953 | G32: 1 | H32: =C32 -> 31 | J32: =$Q$10+$Q$11*H32 -> 222481.56 | L32: =(J32-A32)^2 -> 279371.99
A33: 232803 | C33: 32 | E33: =A33 -> 232803 | G33: 1 | H33: =C33 -> 32 | J33: =$Q$10+$Q$11*H33 -> 225177.15 | L33: =(J33-A33)^2 -> 58153604
A34: 228660 | C34: 33 | E34: =A34 -> 228660 | G34: 1 | H34: =C34 -> 33 | J34: =$Q$10+$Q$11*H34 -> 227872.74 | L34: =(J34-A34)^2 -> 619776.18 | U34: Exact speed
A35: 239816 | C35: 34 | E35: =A35 -> 239816 | G35: 1 | H35: =C35 -> 34 | J35: =$Q$10+$Q$11*H35 -> 230568.33 | L35: =(J35-A35)^2 -> 85519331 | W35: =T28 -> 2695.5924
A36: 233082 | C36: 35 | E36: =A36 -> 233082 | G36: 1 | H36: =C36 -> 35 | J36: =$Q$10+$Q$11*H36 -> 233263.93 | L36: =(J36-A36)^2 -> 33097.135 | W36: Gross value added in the Netherlands changed quarter by quarter by PLN 2,695.59.
A37: 243243 | C37: 36 | E37: =A37 -> 243243 | G37: 1 | H37: =C37 -> 36 | J37: =$Q$10+$Q$11*H37 -> 235959.52 | L37: =(J37-A37)^2 -> 53049101
A38: 241862 | C38: 37 | E38: =A38 -> 241862 | G38: 1 | H38: =C38 -> 37 | J38: =$Q$10+$Q$11*H38 -> 238655.11 | L38: =(J38-A38)^2 -> 10284137 | U38: Average velocity
A39: 255757 | C39: 38 | E39: =A39 -> 255757 | G39: 1 | H39: =C39 -> 38 | J39: =$Q$10+$Q$11*H39 -> 241350.7 | L39: =(J39-A39)^2 -> 2.0754138e+08 | W39: =T28/AVERAGE(J2:J43) -> 0.013692007
A40: 248625 | C40: 39 | E40: =A40 -> 248625 | G40: 1 | H40: =C40 -> 39 | J40: =$Q$10+$Q$11*H40 -> 244046.3 | L40: =(J40-A40)^2 -> 20964532 | W40: Gross value added in the Netherlands changed quarter by quarter by 1,37%.
...

Sheet 03 DA Linear Model
A1: SUMMARY OUTPUT
A3: Regression Statistics
A4: Multiple R | B4: 0.95781475
A5: R Square | B5: 0.91740909
A6: Adjusted R Square | B6: 0.91534432
A7: Standard Error | B7: 10045.441
A8: Observations | B8: 42
A10: ANOVA
B11: df | C11: SS | D11: MS | E11: F | F11: Significance F
A12: Regression | B12: 1 | C12: 4.4836201e+10 | D12: 4.4836201e+10 | E12: 444.31481 | F12: 2.8486105e-23
A13: Residual | B13: 40 | C13: 4.0364354e+09 | D13: 1.0091089e+08
A14: Total | B14: 41 | C14: 4.8872636e+10
B16: Coefficients | C16: Standard Error | D16: t Stat | E16: P-value | F16: Lower 95% | G16: Upper 95% | H16: Lower 95,0% | I16: Upper 95,0%
A17: Intercept | B17: 138918.19 | C17: 3156.29 | D17: 44.013127 | E17: 1.6703398e-35 | F17: 132539.09 | G17: 145297.29 | H17: 132539.09 | I17: 145297.29
A18: X Variable 1 | B18: 2695.5924 | C18: 127.88183 | D18: 21.078776 | E18: 2.8486105e-23 | F18: 2437.1336 | G18: 2954.0512 | H18: 2437.1336 | I18: 2954.0512

Sheet 03 Power Trend
A1: GVA | C1: time
A2: 150816 | C2: 1 | E2: =LN(A2) -> 11.923816 | G2: 1 | H2: =LN(C2) -> 0 | J2: =EXP($V$27)*C2^$V$28 -> 123283.42 | L2: =LN(J2) -> 11.722241 | N2: =(L2-E2)^2 -> 0.040632328 | Q2: {=TRANSPOSE(G2:H43)} -> 1 | R2: 1 | S2: 1 | T2: 1 | U2: 1 | V2: 1 | W2: 1 | X2: 1 | Y2: 1 | Z2: 1 | AA2: 1 | AB2: 1 | AC2: 1 | AD2: 1 | AE2: 1 | AF2: 1 | AG2: 1 | AH2: 1 | AI2: 1 | AJ2: 1 | AK2: 1 | AL2: 1 | AM2: 1 | AN2: 1 | AO2: 1 | AP2: 1 | AQ2: 1 | AR2: 1 | AS2: 1 | AT2: 1 | AU2: 1 | AV2: 1 | AW2: 1 | AX2: 1 | AY2: 1 | AZ2: 1 | BA2: 1 | BB2: 1 | BC2: 1 | BD2: 1 | BE2: 1 | BF2: 1
A3: 159663 | C3: 2 | E3: =LN(A3) -> 11.980821 | G3: 1 | H3: =LN(C3) -> 0.69314718 | J3: =EXP($V$27)*C3^$V$28 -> 137914.27 | L3: =LN(J3) -> 11.834388 | N3: =(L3-E3)^2 -> 0.021442643 | Q3: 0 | R3: 0.69314718 | S3: 1.0986123 | T3: 1.3862944 | U3: 1.6094379 | V3: 1.7917595 | W3: 1.9459101 | X3: 2.0794415 | Y3: 2.1972246 | Z3: 2.3025851 | AA3: 2.3978953 | AB3: 2.4849066 | AC3: 2.5649494 | AD3: 2.6390573 | AE3: 2.7080502 | AF3: 2.7725887 | AG3: 2.8332133 | AH3: 2.8903718 | AI3: 2.944439 | AJ3: 2.9957323 | AK3: 3.0445224 | AL3: 3.0910425 | AM3: 3.1354942 | AN3: 3.1780538 | AO3: 3.2188758 | AP3: 3.2580965 | AQ3: 3.2958369 | AR3: 3.3322045 | AS3: 3.3672958 | AT3: 3.4011974 | AU3: 3.4339872 | AV3: 3.4657359 | AW3: 3.4965076 | AX3: 3.5263605 | AY3: 3.5553481 | AZ3: 3.5835189 | BA3: 3.6109179 | BB3: 3.6375862 | BC3: 3.6635616 | BD3: 3.6888795 | BE3: 3.7135721 | BF3: 3.7376696
A4: 155573 | C4: 3 | E4: =LN(A4) -> 11.95487 | G4: 1 | H4: =LN(C4) -> 1.0986123 | J4: =EXP($V$27)*C4^$V$28 -> 147265 | L4: =LN(J4) -> 11.899989 | N4: =(L4-E4)^2 -> 0.0030119668
A5: 161574 | C5: 4 | E5: =LN(A5) -> 11.992719 | G5: 1 | H5: =LN(C5) -> 1.3862944 | J5: =EXP($V$27)*C5^$V$28 -> 154281.46 | L5: =LN(J5) -> 11.946534 | N5: =(L5-E5)^2 -> 0.0021330187
A6: 154922 | C6: 5 | E6: =LN(A6) -> 11.950677 | G6: 1 | H6: =LN(C6) -> 1.6094379 | J6: =EXP($V$27)*C6^$V$28 -> 159953.27 | L6: =LN(J6) -> 11.982637 | N6: =(L6-E6)^2 -> 0.0010214366 | Q6: {=MMULT(_xlfn.ANCHORARRAY(Q2),G2:H43)} -> 42 | R6: 117.77188 | T6: {=MINVERSE(_xlfn.ANCHORARRAY(Q6))} -> 0.27316217 | U6: -0.088924545
A7: 164049 | C7: 6 | E7: =LN(A7) -> 12.00792 | G7: 1 | H7: =LN(C7) -> 1.7917595 | J7: =EXP($V$27)*C7^$V$28 -> 164741.9 | L7: =LN(J7) -> 12.012135 | N7: =(L7-E7)^2 -> 1.7765141e-05 | Q7: 117.77188 | R7: 361.77663 | T7: -0.088924545 | U7: 0.031712416
A8: 159126 | C8: 7 | E8: =LN(A8) -> 11.977452 | G8: 1 | H8: =LN(C8) -> 1.9459101 | J8: =EXP($V$27)*C8^$V$28 -> 168902.32 | L8: =LN(J8) -> 12.037076 | N8: =(L8-E8)^2 -> 0.0035550443
A9: 166215 | C9: 8 | E9: =LN(A9) -> 12.021037 | G9: 1 | H9: =LN(C9) -> 2.0794415 | J9: =EXP($V$27)*C9^$V$28 -> 172591.06 | L9: =LN(J9) -> 12.05868 | N9: =(L9-E9)^2 -> 0.0014169837
A10: 161419 | C10: 9 | E10: =LN(A10) -> 11.991759 | G10: 1 | H10: =LN(C10) -> 2.1972246 | J10: =EXP($V$27)*C10^$V$28 -> 175911.57 | L10: =LN(J10) -> 12.077737 | N10: =(L10-E10)^2 -> 0.0073922122 | Q10: {=MMULT(_xlfn.ANCHORARRAY(Q2),E2:E43)} -> 511.38879 | S10: {=MMULT(_xlfn.ANCHORARRAY(T6),_xlfn.ANCHORARRAY(Q10))} -> 11.722241
A11: 171164 | C11: 10 | E11: =LN(A11) -> 12.050377 | G11: 1 | H11: =LN(C11) -> 2.3025851 | J11: =EXP($V$27)*C11^$V$28 -> 178935.97 | L11: =LN(J11) -> 12.094783 | N11: =(L11-E11)^2 -> 0.0019718817 | Q11: 1439.0833 | S11: 0.16179298
A12: 166103 | C12: 11 | E12: =LN(A12) -> 12.020363 | G12: 1 | H12: =LN(C12) -> 2.3978953 | J12: =EXP($V$27)*C12^$V$28 -> 181716.64 | L12: =LN(J12) -> 12.110204 | N12: =(L12-E12)^2 -> 0.0080713111
A13: 173248 | C13: 12 | E13: =LN(A13) -> 12.062479 | G13: 1 | H13: =LN(C13) -> 2.4849066 | J13: =EXP($V$27)*C13^$V$28 -> 184292.91 | L13: =LN(J13) -> 12.124282 | N13: =(L13-E13)^2 -> 0.003819523
A14: 170056 | C14: 13 | E14: =LN(A14) -> 12.043883 | G14: 1 | H14: =LN(C14) -> 2.5649494 | J14: =EXP($V$27)*C14^$V$28 -> 186695.09 | L14: =LN(J14) -> 12.137232 | N14: =(L14-E14)^2 -> 0.0087140241
A15: 179008 | C15: 14 | E15: =LN(A15) -> 12.095186 | G15: 1 | H15: =LN(C15) -> 2.6390573 | J15: =EXP($V$27)*C15^$V$28 -> 188947.06 | L15: =LN(J15) -> 12.149222 | N15: =(L15-E15)^2 -> 0.0029199308
A16: 173652 | C16: 15 | E16: =LN(A16) -> 12.064809 | G16: 1 | H16: =LN(C16) -> 2.7080502 | J16: =EXP($V$27)*C16^$V$28 -> 191068.01 | L16: =LN(J16) -> 12.160385 | N16: =(L16-E16)^2 -> 0.0091348 | Q16: =SUM(N2:N43) -> 0.35926746 | S16: =Q16/(COUNT(J2:J43)-2) -> 0.0089816866
A17: 180841 | C17: 16 | E17: =LN(A17) -> 12.105373 | G17: 1 | H17: =LN(C17) -> 2.7725887 | J17: =EXP($V$27)*C17^$V$28 -> 193073.57 | L17: =LN(J17) -> 12.170827 | N17: =(L17-E17)^2 -> 0.0042841125
A18: 178780 | C18: 17 | E18: =LN(A18) -> 12.093911 | G18: 1 | H18: =LN(C18) -> 2.8332133 | J18: =EXP($V$27)*C18^$V$28 -> 194976.68 | L18: =LN(J18) -> 12.180635 | N18: =(L18-E18)^2 -> 0.0075210457
A19: 188735 | C19: 18 | E19: =LN(A19) -> 12.148099 | G19: 1 | H19: =LN(C19) -> 2.8903718 | J19: =EXP($V$27)*C19^$V$28 -> 196788.15 | L19: =LN(J19) -> 12.189883 | N19: =(L19-E19)^2 -> 0.0017458924
A20: 182497 | C20: 19 | E20: =LN(A20) -> 12.114489 | G20: 1 | H20: =LN(C20) -> 2.944439 | J20: =EXP($V$27)*C20^$V$28 -> 198517.15 | L20: =LN(J20) -> 12.198631 | N20: =(L20-E20)^2 -> 0.0070798349
A21: 189496 | C21: 20 | E21: =LN(A21) -> 12.152123 | G21: 1 | H21: =LN(C21) -> 2.9957323 | J21: =EXP($V$27)*C21^$V$28 -> 200171.48 | L21: =LN(J21) -> 12.20693 | N21: =(L21-E21)^2 -> 0.003003749 | Q21: =$S$16*T6 -> 0.002453457 | R21: =$S$16*U6 -> -0.00079869239
A22: 182537 | C22: 21 | E22: =LN(A22) -> 12.114708 | G22: 1 | H22: =LN(C22) -> 3.0445224 | J22: =EXP($V$27)*C22^$V$28 -> 201757.87 | L22: =LN(J22) -> 12.214824 | N22: =(L22-E22)^2 -> 0.010023093 | Q22: =$S$16*T7 -> -0.00079869239 | R22: =$S$16*U7 -> 0.00028483098
A23: 175396 | C23: 22 | E23: =LN(A23) -> 12.074802 | G23: 1 | H23: =LN(C23) -> 3.0910425 | J23: =EXP($V$27)*C23^$V$28 -> 203282.15 | L23: =LN(J23) -> 12.22235 | N23: =(L23-E23)^2 -> 0.021770598
A24: 179815 | C24: 23 | E24: =LN(A24) -> 12.099684 | G24: 1 | H24: =LN(C24) -> 3.1354942 | J24: =EXP($V$27)*C24^$V$28 -> 204749.42 | L24: =LN(J24) -> 12.229542 | N24: =(L24-E24)^2 -> 0.016863189
A25: 188401 | C25: 24 | E25: =LN(A25) -> 12.146328 | G25: 1 | H25: =LN(C25) -> 3.1780538 | J25: =EXP($V$27)*C25^$V$28 -> 206164.16 | L25: =LN(J25) -> 12.236428 | N25: =(L25-E25)^2 -> 0.0081180213
A26: 183940 | C26: 25 | E26: =LN(A26) -> 12.122365 | G26: 1 | H26: =LN(C26) -> 3.2188758 | J26: =EXP($V$27)*C26^$V$28 -> 207530.32 | L26: =LN(J26) -> 12.243033 | N26: =(L26-E26)^2 -> 0.014560725 | AA26: If the p-value is less than 0.1, we conclude that the parameter is statistically significant.
A27: 201433 | C27: 26 | E27: =LN(A27) -> 12.213212 | G27: 1 | H27: =LN(C27) -> 3.2580965 | J27: =EXP($V$27)*C27^$V$28 -> 208851.42 | L27: =LN(J27) -> 12.249378 | N27: =(L27-E27)^2 -> 0.0013079984 | Q27: =SQRT(Q21) -> 0.049532383 | R27: =SQRT(R21) -> #NUM! | U27: 0 | V27: =S10 -> 11.722241 | W27: =Q27 -> 0.049532383 | X27: =V27/W27 -> 236.65813 | Y27: =_xlfn.T.DIST.2T(X27,40) -> 1.4739576e-64 | AA27: Statistically significant
A28: 198942 | C28: 27 | E28: =LN(A28) -> 12.200769 | G28: 1 | H28: =LN(C28) -> 3.2958369 | J28: =EXP($V$27)*C28^$V$28 -> 210130.59 | L28: =LN(J28) -> 12.255484 | N28: =(L28-E28)^2 -> 0.0029938271 | Q28: =SQRT(Q22) -> #NUM! | R28: =SQRT(R22) -> 0.016876936 | U28: 1 | V28: =S11 -> 0.16179298 | W28: =R28 -> 0.016876936 | X28: =V28/W28 -> 9.5866322 | Y28: =_xlfn.T.DIST.2T(X28,40) -> 6.4318424e-12 | AA28: Statistically significant
A29: 207415 | C29: 28 | E29: =LN(A29) -> 12.242477 | G29: 1 | H29: =LN(C29) -> 3.3322045 | J29: =EXP($V$27)*C29^$V$28 -> 211370.65 | L29: =LN(J29) -> 12.261369 | N29: =(L29-E29)^2 -> 0.00035689306
A30: 209214 | C30: 29 | E30: =LN(A30) -> 12.251113 | G30: 1 | H30: =LN(C30) -> 3.3672958 | J30: =EXP($V$27)*C30^$V$28 -> 212574.13 | L30: =LN(J30) -> 12.267046 | N30: =(L30-E30)^2 -> 0.00025386394
A31: 224204 | C31: 30 | E31: =LN(A31) -> 12.320312 | G31: 1 | H31: =LN(C31) -> 3.4011974 | J31: =EXP($V$27)*C31^$V$28 -> 213743.31 | L31: =LN(J31) -> 12.272531 | N31: =(L31-E31)^2 -> 0.0022829818 | W31: Power model formula
A32: 221953 | C32: 31 | E32: =LN(A32) -> 12.310221 | G32: 1 | H32: =LN(C32) -> 3.4339872 | J32: =EXP($V$27)*C32^$V$28 -> 214880.26 | L32: =LN(J32) -> 12.277836 | N32: =(L32-E32)^2 -> 0.0010487682
A33: 232803 | C33: 32 | E33: =LN(A33) -> 12.357948 | G33: 1 | H33: =LN(C33) -> 3.4657359 | J33: =EXP($V$27)*C33^$V$28 -> 215986.88 | L33: =LN(J33) -> 12.282973 | N33: =(L33-E33)^2 -> 0.0056212401
A34: 228660 | C34: 33 | E34: =LN(A34) -> 12.339991 | G34: 1 | H34: =LN(C34) -> 3.4965076 | J34: =EXP($V$27)*C34^$V$28 -> 217064.88 | L34: =LN(J34) -> 12.287952 | N34: =(L34-E34)^2 -> 0.0027081484 | W34: Average speed
A35: 239816 | C35: 34 | E35: =LN(A35) -> 12.387627 | G35: 1 | H35: =LN(C35) -> 3.5263605 | J35: =EXP($V$27)*C35^$V$28 -> 218115.84 | L35: =LN(J35) -> 12.292782 | N35: =(L35-E35)^2 -> 0.0089956976 | Z35: =V28*EXP(V27)*AVERAGE(C2:C43)^(V28-1) -> 1524.0706
A36: 233082 | C36: 35 | E36: =LN(A36) -> 12.359146 | G36: 1 | H36: =LN(C36) -> 3.5553481 | J36: =EXP($V$27)*C36^$V$28 -> 219141.2 | L36: =LN(J36) -> 12.297472 | N36: =(L36-E36)^2 -> 0.0038036862 | Z36: Gross value added in the Netherlands changed quarter by quarter by PLN 1,524.07.
A37: 243243 | C37: 36 | E37: =LN(A37) -> 12.401816 | G37: 1 | H37: =LN(C37) -> 3.5835189 | J37: =EXP($V$27)*C37^$V$28 -> 220142.3 | L37: =LN(J37) -> 12.302029 | N37: =(L37-E37)^2 -> 0.0099574059
A38: 241862 | C38: 37 | E38: =LN(A38) -> 12.396123 | G38: 1 | H38: =LN(C38) -> 3.6109179 | J38: =EXP($V$27)*C38^$V$28 -> 221120.35 | L38: =LN(J38) -> 12.306462 | N38: =(L38-E38)^2 -> 0.0080389537 | W38: Average velocity
A39: 255757 | C39: 38 | E39: =LN(A39) -> 12.451983 | G39: 1 | H39: =LN(C39) -> 3.6375862 | J39: =EXP($V$27)*C39^$V$28 -> 222076.48 | L39: =LN(J39) -> 12.310777 | N39: =(L39-E39)^2 -> 0.019939117 | Z39: =Z35/AVERAGE(J2:J43) -> 0.0077813779
A40: 248625 | C40: 39 | E40: =LN(A40) -> 12.423701 | G40: 1 | H40: =LN(C40) -> 3.6635616 | J40: =EXP($V$27)*C40^$V$28 -> 223011.76 | L40: =LN(J40) -> 12.31498 | N40: =(L40-E40)^2 -> 0.01182031 | Z40: Gross value added in the Netherlands changed quarter by quarter by 0,78%.
...

Sheet 03 DA Power Model
A1: SUMMARY OUTPUT
A3: Regression Statistics
A4: Multiple R | B4: 0.83471435
A5: R Square | B5: 0.69674804
A6: Adjusted R Square | B6: 0.68916674
A7: Standard Error | B7: 0.094771761
A8: Observations | B8: 42
A10: ANOVA
B11: df | C11: SS | D11: MS | E11: F | F11: Significance F
A12: Regression | B12: 1 | C12: 0.82544858 | D12: 0.82544858 | E12: 91.903517 | F12: 6.4318424e-12
A13: Residual | B13: 40 | C13: 0.35926746 | D13: 0.0089816866
A14: Total | B14: 41 | C14: 1.184716
B16: Coefficients | C16: Standard Error | D16: t Stat | E16: P-value | F16: Lower 95% | G16: Upper 95% | H16: Lower 95,0% | I16: Upper 95,0%
A17: Intercept | B17: 11.722241 | C17: 0.049532383 | D17: 236.65813 | E17: 1.4739576e-64 | F17: 11.622133 | G17: 11.82235 | H17: 11.622133 | I17: 11.82235
A18: X Variable 1 | B18: 0.16179298 | C18: 0.016876936 | D18: 9.5866322 | E18: 6.4318424e-12 | F18: 0.12768342 | G18: 0.19590254 | H18: 0.12768342 | I18: 0.19590254

Sheet 03 Exponential Trend
A1: GVA | C1: time
A2: 150816 | C2: 1 | E2: =LN(A2) -> 11.923816 | G2: 1 | H2: =C2 -> 1 | J2: =EXP($V$27+$V$28*C2) -> 147347.02 | L2: =LN(J2) -> 11.900546 | N2: =(L2-E2)^2 -> 0.00054149665 | Q2: {=TRANSPOSE(G2:H43)} -> 1 | R2: 1 | S2: 1 | T2: 1 | U2: 1 | V2: 1 | W2: 1 | X2: 1 | Y2: 1 | Z2: 1 | AA2: 1 | AB2: 1 | AC2: 1 | AD2: 1 | AE2: 1 | AF2: 1 | AG2: 1 | AH2: 1 | AI2: 1 | AJ2: 1 | AK2: 1 | AL2: 1 | AM2: 1 | AN2: 1 | AO2: 1 | AP2: 1 | AQ2: 1 | AR2: 1 | AS2: 1 | AT2: 1 | AU2: 1 | AV2: 1 | AW2: 1 | AX2: 1 | AY2: 1 | AZ2: 1 | BA2: 1 | BB2: 1 | BC2: 1 | BD2: 1 | BE2: 1 | BF2: 1
A3: 159663 | C3: 2 | E3: =LN(A3) -> 11.980821 | G3: 1 | H3: =C3 -> 2 | J3: =EXP($V$27+$V$28*C3) -> 149339.69 | L3: =LN(J3) -> 11.913979 | N3: =(L3-E3)^2 -> 0.0044678268 | Q3: 1 | R3: 2 | S3: 3 | T3: 4 | U3: 5 | V3: 6 | W3: 7 | X3: 8 | Y3: 9 | Z3: 10 | AA3: 11 | AB3: 12 | AC3: 13 | AD3: 14 | AE3: 15 | AF3: 16 | AG3: 17 | AH3: 18 | AI3: 19 | AJ3: 20 | AK3: 21 | AL3: 22 | AM3: 23 | AN3: 24 | AO3: 25 | AP3: 26 | AQ3: 27 | AR3: 28 | AS3: 29 | AT3: 30 | AU3: 31 | AV3: 32 | AW3: 33 | AX3: 34 | AY3: 35 | AZ3: 36 | BA3: 37 | BB3: 38 | BC3: 39 | BD3: 40 | BE3: 41 | BF3: 42
A4: 155573 | C4: 3 | E4: =LN(A4) -> 11.95487 | G4: 1 | H4: =C4 -> 3 | J4: =EXP($V$27+$V$28*C4) -> 151359.32 | L4: =LN(J4) -> 11.927412 | N4: =(L4-E4)^2 -> 0.00075396731
A5: 161574 | C5: 4 | E5: =LN(A5) -> 11.992719 | G5: 1 | H5: =C5 -> 4 | J5: =EXP($V$27+$V$28*C5) -> 153406.26 | L5: =LN(J5) -> 11.940845 | N5: =(L5-E5)^2 -> 0.0026908665
A6: 154922 | C6: 5 | E6: =LN(A6) -> 11.950677 | G6: 1 | H6: =C6 -> 5 | J6: =EXP($V$27+$V$28*C6) -> 155480.88 | L6: =LN(J6) -> 11.954278 | N6: =(L6-E6)^2 -> 1.2967091e-05 | Q6: {=MMULT(_xlfn.ANCHORARRAY(Q2),G2:H43)} -> 42 | R6: 903 | T6: {=MINVERSE(_xlfn.ANCHORARRAY(Q6))} -> 0.098722416 | U6: -0.0034843206
A7: 164049 | C7: 6 | E7: =LN(A7) -> 12.00792 | G7: 1 | H7: =C7 -> 6 | J7: =EXP($V$27+$V$28*C7) -> 157583.55 | L7: =LN(J7) -> 11.967711 | N7: =(L7-E7)^2 -> 0.0016167914 | Q7: 903 | R7: 25585 | T7: -0.0034843206 | U7: 0.00016206142
A8: 159126 | C8: 7 | E8: =LN(A8) -> 11.977452 | G8: 1 | H8: =C8 -> 7 | J8: =EXP($V$27+$V$28*C8) -> 159714.67 | L8: =LN(J8) -> 11.981144 | N8: =(L8-E8)^2 -> 1.3634907e-05
A9: 166215 | C9: 8 | E9: =LN(A9) -> 12.021037 | G9: 1 | H9: =C9 -> 8 | J9: =EXP($V$27+$V$28*C9) -> 161874.6 | L9: =LN(J9) -> 11.994577 | N9: =(L9-E9)^2 -> 0.00070014073
A10: 161419 | C10: 9 | E10: =LN(A10) -> 11.991759 | G10: 1 | H10: =C10 -> 9 | J10: =EXP($V$27+$V$28*C10) -> 164063.74 | L10: =LN(J10) -> 12.00801 | N10: =(L10-E10)^2 -> 0.00026411318 | Q10: {=MMULT(_xlfn.ANCHORARRAY(Q2),E2:E43)} -> 511.38879 | S10: {=MMULT(_xlfn.ANCHORARRAY(T6),_xlfn.ANCHORARRAY(Q10))} -> 11.887113
A11: 171164 | C11: 10 | E11: =LN(A11) -> 12.050377 | G11: 1 | H11: =C11 -> 10 | J11: =EXP($V$27+$V$28*C11) -> 166282.49 | L11: =LN(J11) -> 12.021443 | N11: =(L11-E11)^2 -> 0.00083718001 | Q11: 11077.748 | S11: 0.01343307
A12: 166103 | C12: 11 | E12: =LN(A12) -> 12.020363 | G12: 1 | H12: =C12 -> 11 | J12: =EXP($V$27+$V$28*C12) -> 168531.25 | L12: =LN(J12) -> 12.034876 | N12: =(L12-E12)^2 -> 0.00021062978
A13: 173248 | C13: 12 | E13: =LN(A13) -> 12.062479 | G13: 1 | H13: =C13 -> 12 | J13: =EXP($V$27+$V$28*C13) -> 170810.41 | L13: =LN(J13) -> 12.04831 | N13: =(L13-E13)^2 -> 0.00020078483
A14: 170056 | C14: 13 | E14: =LN(A14) -> 12.043883 | G14: 1 | H14: =C14 -> 13 | J14: =EXP($V$27+$V$28*C14) -> 173120.4 | L14: =LN(J14) -> 12.061743 | N14: =(L14-E14)^2 -> 0.0003189622
A15: 179008 | C15: 14 | E15: =LN(A15) -> 12.095186 | G15: 1 | H15: =C15 -> 14 | J15: =EXP($V$27+$V$28*C15) -> 175461.63 | L15: =LN(J15) -> 12.075176 | N15: =(L15-E15)^2 -> 0.00040040492
A16: 173652 | C16: 15 | E16: =LN(A16) -> 12.064809 | G16: 1 | H16: =C16 -> 15 | J16: =EXP($V$27+$V$28*C16) -> 177834.52 | L16: =LN(J16) -> 12.088609 | N16: =(L16-E16)^2 -> 0.00056644715 | Q16: =SUM(N2:N43) -> 0.071265592 | S16: =Q16/(COUNT(J2:J43)-2) -> 0.0017816398
A17: 180841 | C17: 16 | E17: =LN(A17) -> 12.105373 | G17: 1 | H17: =C17 -> 16 | J17: =EXP($V$27+$V$28*C17) -> 180239.5 | L17: =LN(J17) -> 12.102042 | N17: =(L17-E17)^2 -> 1.1100062e-05
A18: 178780 | C18: 17 | E18: =LN(A18) -> 12.093911 | G18: 1 | H18: =C18 -> 17 | J18: =EXP($V$27+$V$28*C18) -> 182677 | L18: =LN(J18) -> 12.115475 | N18: =(L18-E18)^2 -> 0.00046498827
A19: 188735 | C19: 18 | E19: =LN(A19) -> 12.148099 | G19: 1 | H19: =C19 -> 18 | J19: =EXP($V$27+$V$28*C19) -> 185147.47 | L19: =LN(J19) -> 12.128908 | N19: =(L19-E19)^2 -> 0.00036830441
A20: 182497 | C20: 19 | E20: =LN(A20) -> 12.114489 | G20: 1 | H20: =C20 -> 19 | J20: =EXP($V$27+$V$28*C20) -> 187651.35 | L20: =LN(J20) -> 12.142341 | N20: =(L20-E20)^2 -> 0.00077573342
A21: 189496 | C21: 20 | E21: =LN(A21) -> 12.152123 | G21: 1 | H21: =C21 -> 20 | J21: =EXP($V$27+$V$28*C21) -> 190189.09 | L21: =LN(J21) -> 12.155774 | N21: =(L21-E21)^2 -> 1.3328921e-05 | Q21: =$S$16*T6 -> 0.00017588778 | R21: =$S$16*U6 -> -6.2078042e-06
A22: 182537 | C22: 21 | E22: =LN(A22) -> 12.114708 | G22: 1 | H22: =C22 -> 21 | J22: =EXP($V$27+$V$28*C22) -> 192761.15 | L22: =LN(J22) -> 12.169207 | N22: =(L22-E22)^2 -> 0.0029701381 | Q22: =$S$16*T7 -> -6.2078042e-06 | R22: =$S$16*U7 -> 2.8873508e-07
A23: 175396 | C23: 22 | E23: =LN(A23) -> 12.074802 | G23: 1 | H23: =C23 -> 22 | J23: =EXP($V$27+$V$28*C23) -> 195368 | L23: =LN(J23) -> 12.18264 | N23: =(L23-E23)^2 -> 0.011629177
A24: 179815 | C24: 23 | E24: =LN(A24) -> 12.099684 | G24: 1 | H24: =C24 -> 23 | J24: =EXP($V$27+$V$28*C24) -> 198010.09 | L24: =LN(J24) -> 12.196073 | N24: =(L24-E24)^2 -> 0.0092909281
A25: 188401 | C25: 24 | E25: =LN(A25) -> 12.146328 | G25: 1 | H25: =C25 -> 24 | J25: =EXP($V$27+$V$28*C25) -> 200687.92 | L25: =LN(J25) -> 12.209506 | N25: =(L25-E25)^2 -> 0.0039915108
A26: 183940 | C26: 25 | E26: =LN(A26) -> 12.122365 | G26: 1 | H26: =C26 -> 25 | J26: =EXP($V$27+$V$28*C26) -> 203401.97 | L26: =LN(J26) -> 12.222939 | N26: =(L26-E26)^2 -> 0.010115235 | AA26: If the p-value is less than 0.1, we conclude that the parameter is statistically significant.
A27: 201433 | C27: 26 | E27: =LN(A27) -> 12.213212 | G27: 1 | H27: =C27 -> 26 | J27: =EXP($V$27+$V$28*C27) -> 206152.71 | L27: =LN(J27) -> 12.236372 | N27: =(L27-E27)^2 -> 0.00053640386 | Q27: =SQRT(Q21) -> 0.013262269 | R27: =SQRT(R21) -> #NUM! | U27: 0 | V27: =S10 -> 11.887113 | W27: =Q27 -> 0.013262269 | X27: =V27/W27 -> 896.31062 | Y27: =_xlfn.T.DIST.2T(X27,40) -> 1.0980752e-87 | AA27: Statistically significant
A28: 198942 | C28: 27 | E28: =LN(A28) -> 12.200769 | G28: 1 | H28: =C28 -> 27 | J28: =EXP($V$27+$V$28*C28) -> 208940.66 | L28: =LN(J28) -> 12.249806 | N28: =(L28-E28)^2 -> 0.0024046233 | Q28: =SQRT(Q22) -> #NUM! | R28: =SQRT(R22) -> 0.00053734075 | U28: 1 | V28: =S11 -> 0.01343307 | W28: =R28 -> 0.00053734075 | X28: =V28/W28 -> 24.999165 | Y28: =_xlfn.T.DIST.2T(X28,40) -> 4.9695921e-26 | AA28: Statistically significant
A29: 207415 | C29: 28 | E29: =LN(A29) -> 12.242477 | G29: 1 | H29: =C29 -> 28 | J29: =EXP($V$27+$V$28*C29) -> 211766.31 | L29: =LN(J29) -> 12.263239 | N29: =(L29-E29)^2 -> 0.0004310497
A30: 209214 | C30: 29 | E30: =LN(A30) -> 12.251113 | G30: 1 | H30: =C30 -> 29 | J30: =EXP($V$27+$V$28*C30) -> 214630.17 | L30: =LN(J30) -> 12.276672 | N30: =(L30-E30)^2 -> 0.00065325082
A31: 224204 | C31: 30 | E31: =LN(A31) -> 12.320312 | G31: 1 | H31: =C31 -> 30 | J31: =EXP($V$27+$V$28*C31) -> 217532.77 | L31: =LN(J31) -> 12.290105 | N31: =(L31-E31)^2 -> 0.0009124543 | W31: Exponential model formula
A32: 221953 | C32: 31 | E32: =LN(A32) -> 12.310221 | G32: 1 | H32: =C32 -> 31 | J32: =EXP($V$27+$V$28*C32) -> 220474.61 | L32: =LN(J32) -> 12.303538 | N32: =(L32-E32)^2 -> 4.4663622e-05
A33: 232803 | C33: 32 | E33: =LN(A33) -> 12.357948 | G33: 1 | H33: =C33 -> 32 | J33: =EXP($V$27+$V$28*C33) -> 223456.25 | L33: =LN(J33) -> 12.316971 | N33: =(L33-E33)^2 -> 0.001679112
A34: 228660 | C34: 33 | E34: =LN(A34) -> 12.339991 | G34: 1 | H34: =C34 -> 33 | J34: =EXP($V$27+$V$28*C34) -> 226478.2 | L34: =LN(J34) -> 12.330404 | N34: =(L34-E34)^2 -> 9.1919804e-05 | W34: Average speed
A35: 239816 | C35: 34 | E35: =LN(A35) -> 12.387627 | G35: 1 | H35: =C35 -> 34 | J35: =EXP($V$27+$V$28*C35) -> 229541.03 | L35: =LN(J35) -> 12.343837 | N35: =(L35-E35)^2 -> 0.0019175808 | Z35: =V28*EXP(V27+V28*AVERAGE(C2:C43)) -> 2606.8242
A36: 233082 | C36: 35 | E36: =LN(A36) -> 12.359146 | G36: 1 | H36: =C36 -> 35 | J36: =EXP($V$27+$V$28*C36) -> 232645.27 | L36: =LN(J36) -> 12.35727 | N36: =(L36-E36)^2 -> 3.5174289e-06 | Z36: Gross value added in the Netherlands changed quarter by quarter by PLN 2,606.82.
A37: 243243 | C37: 36 | E37: =LN(A37) -> 12.401816 | G37: 1 | H37: =C37 -> 36 | J37: =EXP($V$27+$V$28*C37) -> 235791.49 | L37: =LN(J37) -> 12.370703 | N37: =(L37-E37)^2 -> 0.00096802075
A38: 241862 | C38: 37 | E38: =LN(A38) -> 12.396123 | G38: 1 | H38: =C38 -> 37 | J38: =EXP($V$27+$V$28*C38) -> 238980.27 | L38: =LN(J38) -> 12.384136 | N38: =(L38-E38)^2 -> 0.0001436722 | W38: Average velocity
A39: 255757 | C39: 38 | E39: =LN(A39) -> 12.451983 | G39: 1 | H39: =C39 -> 38 | J39: =EXP($V$27+$V$28*C39) -> 242212.16 | L39: =LN(J39) -> 12.397569 | N39: =(L39-E39)^2 -> 0.0029608533 | Z39: =Z35/AVERAGE(J2:J43) -> 0.013256649
A40: 248625 | C40: 39 | E40: =LN(A40) -> 12.423701 | G40: 1 | H40: =C40 -> 39 | J40: =EXP($V$27+$V$28*C40) -> 245487.77 | L40: =LN(J40) -> 12.411002 | N40: =(L40-E40)^2 -> 0.00016125485 | Z40: Gross value added in the Netherlands changed quarter by quarter by 1,33%.
...

Sheet 03 DA Exponential Model
A1: SUMMARY OUTPUT
A3: Regression Statistics
A4: Multiple R | B4: 0.96945647
A5: R Square | B5: 0.93984585
A6: Adjusted R Square | B6: 0.93834199
A7: Standard Error | B7: 0.042209475
A8: Observations | B8: 42
A10: ANOVA
B11: df | C11: SS | D11: MS | E11: F | F11: Significance F
A12: Regression | B12: 1 | C12: 1.1134505 | D12: 1.1134505 | E12: 624.95823 | F12: 4.9695921e-26
A13: Residual | B13: 40 | C13: 0.071265592 | D13: 0.0017816398
A14: Total | B14: 41 | C14: 1.184716
B16: Coefficients | C16: Standard Error | D16: t Stat | E16: P-value | F16: Lower 95% | G16: Upper 95% | H16: Lower 95,0% | I16: Upper 95,0%
A17: Intercept | B17: 11.887113 | C17: 0.013262269 | D17: 896.31062 | E17: 1.0980752e-87 | F17: 11.860309 | G17: 11.913917 | H17: 11.860309 | I17: 11.913917
A18: X Variable 1 | B18: 0.01343307 | C18: 0.00053734075 | D18: 24.999165 | E18: 4.9695921e-26 | F18: 0.012347064 | G18: 0.014519076 | H18: 0.012347064 | I18: 0.014519076

Sheet 04 Quadratic Trend
A1: GVA | C1: time
A2: 150816 | C2: 1 | E2: =A2 -> 150816 | G2: 1 | H2: =C2 -> 1 | I2: =C2^2 -> 1 | K2: =$V$31+$V$33*C2^2 -> 157572.51 | M2: =(K2-A2)^2 -> 45650458 | P2: {=TRANSPOSE(G2:I43)} -> 1 | Q2: 1 | R2: 1 | S2: 1 | T2: 1 | U2: 1 | V2: 1 | W2: 1 | X2: 1 | Y2: 1 | Z2: 1 | AA2: 1 | AB2: 1 | AC2: 1 | AD2: 1 | AE2: 1 | AF2: 1 | AG2: 1 | AH2: 1 | AI2: 1 | AJ2: 1 | AK2: 1 | AL2: 1 | AM2: 1 | AN2: 1 | AO2: 1 | AP2: 1 | AQ2: 1 | AR2: 1 | AS2: 1 | AT2: 1 | AU2: 1 | AV2: 1 | AW2: 1 | AX2: 1 | AY2: 1 | AZ2: 1 | BA2: 1 | BB2: 1 | BC2: 1 | BD2: 1 | BE2: 1
A3: 159663 | C3: 2 | E3: =A3 -> 159663 | G3: 1 | H3: =C3 -> 2 | I3: =C3^2 -> 4 | K3: =$V$31+$V$33*C3^2 -> 157749.42 | M3: =(K3-A3)^2 -> 3661774.5 | P3: 1 | Q3: 2 | R3: 3 | S3: 4 | T3: 5 | U3: 6 | V3: 7 | W3: 8 | X3: 9 | Y3: 10 | Z3: 11 | AA3: 12 | AB3: 13 | AC3: 14 | AD3: 15 | AE3: 16 | AF3: 17 | AG3: 18 | AH3: 19 | AI3: 20 | AJ3: 21 | AK3: 22 | AL3: 23 | AM3: 24 | AN3: 25 | AO3: 26 | AP3: 27 | AQ3: 28 | AR3: 29 | AS3: 30 | AT3: 31 | AU3: 32 | AV3: 33 | AW3: 34 | AX3: 35 | AY3: 36 | AZ3: 37 | BA3: 38 | BB3: 39 | BC3: 40 | BD3: 41 | BE3: 42
A4: 155573 | C4: 3 | E4: =A4 -> 155573 | G4: 1 | H4: =C4 -> 3 | I4: =C4^2 -> 9 | K4: =$V$31+$V$33*C4^2 -> 158044.28 | M4: =(K4-A4)^2 -> 6107204.6 | P4: 1 | Q4: 4 | R4: 9 | S4: 16 | T4: 25 | U4: 36 | V4: 49 | W4: 64 | X4: 81 | Y4: 100 | Z4: 121 | AA4: 144 | AB4: 169 | AC4: 196 | AD4: 225 | AE4: 256 | AF4: 289 | AG4: 324 | AH4: 361 | AI4: 400 | AJ4: 441 | AK4: 484 | AL4: 529 | AM4: 576 | AN4: 625 | AO4: 676 | AP4: 729 | AQ4: 784 | AR4: 841 | AS4: 900 | AT4: 961 | AU4: 1024 | AV4: 1089 | AW4: 1156 | AX4: 1225 | AY4: 1296 | AZ4: 1369 | BA4: 1444 | BB4: 1521 | BC4: 1600 | BD4: 1681 | BE4: 1764
A5: 161574 | C5: 4 | E5: =A5 -> 161574 | G5: 1 | H5: =C5 -> 4 | I5: =C5^2 -> 16 | K5: =$V$31+$V$33*C5^2 -> 158457.07 | M5: =(K5-A5)^2 -> 9715258.3
A6: 154922 | C6: 5 | E6: =A6 -> 154922 | G6: 1 | H6: =C6 -> 5 | I6: =C6^2 -> 25 | K6: =$V$31+$V$33*C6^2 -> 158987.8 | M6: =(K6-A6)^2 -> 16530756
A7: 164049 | C7: 6 | E7: =A7 -> 164049 | G7: 1 | H7: =C7 -> 6 | I7: =C7^2 -> 36 | K7: =$V$31+$V$33*C7^2 -> 159636.48 | M7: =(K7-A7)^2 -> 19470349 | P7: {=MMULT(_xlfn.ANCHORARRAY(P2),G2:I43)} -> 42 | Q7: 903 | R7: 25585 | T7: {=MINVERSE(_xlfn.ANCHORARRAY(P7))} -> 0.23606272 | U7: -0.022212544 | V7: 0.00043554007
A8: 159126 | C8: 7 | E8: =A8 -> 159126 | G8: 1 | H8: =C8 -> 7 | I8: =C8^2 -> 49 | K8: =$V$31+$V$33*C8^2 -> 160403.09 | M8: =(K8-A8)^2 -> 1630969.4 | P8: 903 | Q8: 25585 | R8: 815409 | T8: -0.022212544 | U8: 0.00271591 | V8: -5.9391828e-05
A9: 166215 | C9: 8 | E9: =A9 -> 166215 | G9: 1 | H9: =C9 -> 8 | I9: =C9^2 -> 64 | K9: =$V$31+$V$33*C9^2 -> 161287.65 | M9: =(K9-A9)^2 -> 24278769 | P9: 25585 | Q9: 815409 | R9: 27718789 | T9: 0.00043554007 | U9: -5.9391828e-05 | V9: 1.3812053e-06
A10: 161419 | C10: 9 | E10: =A10 -> 161419 | G10: 1 | H10: =C10 -> 9 | I10: =C10^2 -> 81 | K10: =$V$31+$V$33*C10^2 -> 162290.15 | M10: =(K10-A10)^2 -> 758900.01
A11: 171164 | C11: 10 | E11: =A11 -> 171164 | G11: 1 | H11: =C11 -> 10 | I11: =C11^2 -> 100 | K11: =$V$31+$V$33*C11^2 -> 163410.59 | M11: =(K11-A11)^2 -> 60115408
A12: 166103 | C12: 11 | E12: =A12 -> 166103 | G12: 1 | H12: =C12 -> 11 | I12: =C12^2 -> 121 | K12: =$V$31+$V$33*C12^2 -> 164648.97 | M12: =(K12-A12)^2 -> 2114212.3 | P12: {=MMULT(_xlfn.ANCHORARRAY(P2),E2:E43)} -> 8268684 | R12: {=MMULT(_xlfn.ANCHORARRAY(T7),_xlfn.ANCHORARRAY(P12))} -> 157513.54
A13: 173248 | C13: 12 | E13: =A13 -> 173248 | G13: 1 | H13: =C13 -> 12 | I13: =C13^2 -> 144 | K13: =$V$31+$V$33*C13^2 -> 166005.29 | M13: =(K13-A13)^2 -> 52456887 | P13: 194409859 | R13: 159.86285
A14: 170056 | C14: 13 | E14: =A14 -> 170056 | G14: 1 | H14: =C14 -> 13 | I14: =C14^2 -> 169 | K14: =$V$31+$V$33*C14^2 -> 167479.55 | M14: =(K14-A14)^2 -> 6638101.2 | P14: 5794927173 | R14: 58.970455
A15: 179008 | C15: 14 | E15: =A15 -> 179008 | G15: 1 | H15: =C15 -> 14 | I15: =C15^2 -> 196 | K15: =$V$31+$V$33*C15^2 -> 169071.75 | M15: =(K15-A15)^2 -> 98729044
A16: 173652 | C16: 15 | E16: =A16 -> 173652 | G16: 1 | H16: =C16 -> 15 | I16: =C16^2 -> 225 | K16: =$V$31+$V$33*C16^2 -> 170781.89 | M16: =(K16-A16)^2 -> 8237507.3
A17: 180841 | C17: 16 | E17: =A17 -> 180841 | G17: 1 | H17: =C17 -> 16 | I17: =C17^2 -> 256 | K17: =$V$31+$V$33*C17^2 -> 172609.98 | M17: =(K17-A17)^2 -> 67749718
A18: 178780 | C18: 17 | E18: =A18 -> 178780 | G18: 1 | H18: =C18 -> 17 | I18: =C18^2 -> 289 | K18: =$V$31+$V$33*C18^2 -> 174556 | M18: =(K18-A18)^2 -> 17842148
A19: 188735 | C19: 18 | E19: =A19 -> 188735 | G19: 1 | H19: =C19 -> 18 | I19: =C19^2 -> 324 | K19: =$V$31+$V$33*C19^2 -> 176619.97 | M19: =(K19-A19)^2 -> 1.4677397e+08 | P19: =SUM(M2:M43) -> 2.1725499e+09 | R19: =P19/(COUNT(K2:K43)-3) -> 55706408
A20: 182497 | C20: 19 | E20: =A20 -> 182497 | G20: 1 | H20: =C20 -> 19 | I20: =C20^2 -> 361 | K20: =$V$31+$V$33*C20^2 -> 178801.88 | M20: =(K20-A20)^2 -> 13653941
A21: 189496 | C21: 20 | E21: =A21 -> 189496 | G21: 1 | H21: =C21 -> 20 | I21: =C21^2 -> 400 | K21: =$V$31+$V$33*C21^2 -> 181101.72 | M21: =(K21-A21)^2 -> 70463872
A22: 182537 | C22: 21 | E22: =A22 -> 182537 | G22: 1 | H22: =C22 -> 21 | I22: =C22^2 -> 441 | K22: =$V$31+$V$33*C22^2 -> 183519.51 | M22: =(K22-A22)^2 -> 965330.83
A23: 175396 | C23: 22 | E23: =A23 -> 175396 | G23: 1 | H23: =C23 -> 22 | I23: =C23^2 -> 484 | K23: =$V$31+$V$33*C23^2 -> 186055.24 | M23: =(K23-A23)^2 -> 1.1361944e+08
A24: 179815 | C24: 23 | E24: =A24 -> 179815 | G24: 1 | H24: =C24 -> 23 | I24: =C24^2 -> 529 | K24: =$V$31+$V$33*C24^2 -> 188708.91 | M24: =(K24-A24)^2 -> 79101681 | P24: =$R$19*T7 -> 13150206 | Q24: =$R$19*U7 -> -1237381 | R24: =$R$19*V7 -> 24262.373
A25: 188401 | C25: 24 | E25: =A25 -> 188401 | G25: 1 | H25: =C25 -> 24 | I25: =C25^2 -> 576 | K25: =$V$31+$V$33*C25^2 -> 191480.52 | M25: =(K25-A25)^2 -> 9483467.7 | P25: =$R$19*T8 -> -1237381 | Q25: =$R$19*U8 -> 151293.59 | R25: =$R$19*V8 -> -3308.5054
A26: 183940 | C26: 25 | E26: =A26 -> 183940 | G26: 1 | H26: =C26 -> 25 | I26: =C26^2 -> 625 | K26: =$V$31+$V$33*C26^2 -> 194370.08 | M26: =(K26-A26)^2 -> 1.0878649e+08 | P26: =$R$19*T9 -> 24262.373 | Q26: =$R$19*U9 -> -3308.5054 | R26: =$R$19*V9 -> 76.941985
A27: 201433 | C27: 26 | E27: =A27 -> 201433 | G27: 1 | H27: =C27 -> 26 | I27: =C27^2 -> 676 | K27: =$V$31+$V$33*C27^2 -> 197377.57 | M27: =(K27-A27)^2 -> 16446517
A28: 198942 | C28: 27 | E28: =A28 -> 198942 | G28: 1 | H28: =C28 -> 27 | I28: =C28^2 -> 729 | K28: =$V$31+$V$33*C28^2 -> 200503 | M28: =(K28-A28)^2 -> 2436732.2
A29: 207415 | C29: 28 | E29: =A29 -> 207415 | G29: 1 | H29: =C29 -> 28 | I29: =C29^2 -> 784 | K29: =$V$31+$V$33*C29^2 -> 203746.38 | M29: =(K29-A29)^2 -> 13458783
A30: 209214 | C30: 29 | E30: =A30 -> 209214 | G30: 1 | H30: =C30 -> 29 | I30: =C30^2 -> 841 | K30: =$V$31+$V$33*C30^2 -> 207107.69 | M30: =(K30-A30)^2 -> 4436522.7 | AA30: If the p-value is less than 0.1, we conclude that the parameter is statistically significant.
A31: 224204 | C31: 30 | E31: =A31 -> 224204 | G31: 1 | H31: =C31 -> 30 | I31: =C31^2 -> 900 | K31: =$V$31+$V$33*C31^2 -> 210586.95 | M31: =(K31-A31)^2 -> 1.8542401e+08 | P31: =SQRT(P24) -> 3626.3213 | Q31: =SQRT(Q24) -> #NUM! | R31: =SQRT(R24) -> 155.76384 | U31: 0 | V31: =R12 -> 157513.54 | W31: =P31 -> 3626.3213 | X31: =V31/W31 -> 43.436179 | Y31: =_xlfn.T.DIST.2T(X31,COUNT($K$2:$K$43)-3) -> 1.213731e-34 | AA31: Statistically significant
A32: 221953 | C32: 31 | E32: =A32 -> 221953 | G32: 1 | H32: =C32 -> 31 | I32: =C32^2 -> 961 | K32: =$V$31+$V$33*C32^2 -> 214184.15 | M32: =(K32-A32)^2 -> 60355043 | P32: =SQRT(P25) -> #NUM! | Q32: =SQRT(Q25) -> 388.96477 | R32: =SQRT(R25) -> #NUM! | U32: 1 | V32: =R13 -> 159.86285 | W32: =Q32 -> 388.96477 | X32: =V32/W32 -> 0.4109957 | Y32: =_xlfn.T.DIST.2T(X32,COUNT($K$2:$K$43)-3) -> 0.68332534 | AA32: Not statistically significant so we do not consider this parameter
A33: 232803 | C33: 32 | E33: =A33 -> 232803 | G33: 1 | H33: =C33 -> 32 | I33: =C33^2 -> 1024 | K33: =$V$31+$V$33*C33^2 -> 217899.29 | M33: =(K33-A33)^2 -> 2.2212064e+08 | P33: =SQRT(P26) -> 155.76384 | Q33: =SQRT(Q26) -> #NUM! | R33: =SQRT(R26) -> 8.7716581 | U33: 2 | V33: =R14 -> 58.970455 | W33: =R33 -> 8.7716581 | X33: =V33/W33 -> 6.7228402 | Y33: =_xlfn.T.DIST.2T(X33,COUNT($K$2:$K$43)-3) -> 5.1583723e-08 | AA33: Statistically significant
A34: 228660 | C34: 33 | E34: =A34 -> 228660 | G34: 1 | H34: =C34 -> 33 | I34: =C34^2 -> 1089 | K34: =$V$31+$V$33*C34^2 -> 221732.37 | M34: =(K34-A34)^2 -> 47992093
A35: 239816 | C35: 34 | E35: =A35 -> 239816 | G35: 1 | H35: =C35 -> 34 | I35: =C35^2 -> 1156 | K35: =$V$31+$V$33*C35^2 -> 225683.39 | M35: =(K35-A35)^2 -> 1.9973072e+08
A36: 233082 | C36: 35 | E36: =A36 -> 233082 | G36: 1 | H36: =C36 -> 35 | I36: =C36^2 -> 1225 | K36: =$V$31+$V$33*C36^2 -> 229752.35 | M36: =(K36-A36)^2 -> 11086574
A37: 243243 | C37: 36 | E37: =A37 -> 243243 | G37: 1 | H37: =C37 -> 36 | I37: =C37^2 -> 1296 | K37: =$V$31+$V$33*C37^2 -> 233939.25 | M37: =(K37-A37)^2 -> 86559734 | V37: Linear model formula
A38: 241862 | C38: 37 | E38: =A38 -> 241862 | G38: 1 | H38: =C38 -> 37 | I38: =C38^2 -> 1369 | K38: =$V$31+$V$33*C38^2 -> 238244.09 | M38: =(K38-A38)^2 -> 13089238 | Z38: Because parameter is not statistycally significant.
A39: 255757 | C39: 38 | E39: =A39 -> 255757 | G39: 1 | H39: =C39 -> 38 | I39: =C39^2 -> 1444 | K39: =$V$31+$V$33*C39^2 -> 242666.88 | M39: =(K39-A39)^2 -> 1.7135127e+08
A40: 248625 | C40: 39 | E40: =A40 -> 248625 | G40: 1 | H40: =C40 -> 39 | I40: =C40^2 -> 1521 | K40: =$V$31+$V$33*C40^2 -> 247207.6 | M40: =(K40-A40)^2 -> 2009011.4 | V40: Average speed
...

Sheet 04 Logistic Trend
A1: GVA | C1: time | L1: =COUNT(E2:E43)*0.25 -> 10.5
A2: 150816 | C2: 1 | E2: =A2 -> 150816 | G2: =$L$4/(1+$L$5*EXP(-$L$6*C2)) -> 170242.96 | I2: =(G2-A2)^2 -> 3.7740663e+08 | L2: =COUNT(E2:E43)*0.75 -> 31.5
A3: 159663 | C3: 2 | E3: =A3 -> 159663 | G3: =$L$4/(1+$L$5*EXP(-$L$6*C3)) -> 174311.84 | I3: =(G3-A3)^2 -> 2.1458852e+08
A4: 155573 | C4: 3 | E4: =A4 -> 155573 | G4: =$L$4/(1+$L$5*EXP(-$L$6*C4)) -> 178302.96 | I4: =(G4-A4)^2 -> 5.1665111e+08 | L4: =MAX(E2:E43) -> 269320
A5: 161574 | C5: 4 | E5: =A5 -> 161574 | G5: =$L$4/(1+$L$5*EXP(-$L$6*C5)) -> 182210.21 | I5: =(G5-A5)^2 -> 4.2585303e+08 | L5: =(L4-E12)/E12 -> 0.62140359
A6: 154922 | C6: 5 | E6: =A6 -> 154922 | G6: =$L$4/(1+$L$5*EXP(-$L$6*C6)) -> 186028.07 | I6: =(G6-A6)^2 -> 9.6758785e+08 | L6: =ABS( ((1)/(C33-C12)) * LN( ((L4-E33)/(E33)) / ((L4-E12)/(E12)) ) ) -> 0.065554295
A7: 164049 | C7: 6 | E7: =A7 -> 164049 | G7: =$L$4/(1+$L$5*EXP(-$L$6*C7)) -> 189751.68 | I7: =(G7-A7)^2 -> 6.6062785e+08
A8: 159126 | C8: 7 | E8: =A8 -> 159126 | G8: =$L$4/(1+$L$5*EXP(-$L$6*C8)) -> 193376.78 | I8: =(G8-A8)^2 -> 1.173116e+09
A9: 166215 | C9: 8 | E9: =A9 -> 166215 | G9: =$L$4/(1+$L$5*EXP(-$L$6*C9)) -> 196899.76 | I9: =(G9-A9)^2 -> 9.4155423e+08
A10: 161419 | C10: 9 | E10: =A10 -> 161419 | G10: =$L$4/(1+$L$5*EXP(-$L$6*C10)) -> 200317.62 | I10: =(G10-A10)^2 -> 1.5131024e+09
A11: 171164 | C11: 10 | E11: =A11 -> 171164 | G11: =$L$4/(1+$L$5*EXP(-$L$6*C11)) -> 203627.99 | I11: =(G11-A11)^2 -> 1.0539107e+09
A12: 166103 | C12: 11 | E12: =A12 -> 166103 | G12: =$L$4/(1+$L$5*EXP(-$L$6*C12)) -> 206829.09 | I12: =(G12-A12)^2 -> 1.6586146e+09
A13: 173248 | C13: 12 | E13: =A13 -> 173248 | G13: =$L$4/(1+$L$5*EXP(-$L$6*C13)) -> 209919.71 | I13: =(G13-A13)^2 -> 1.3448144e+09
A14: 170056 | C14: 13 | E14: =A14 -> 170056 | G14: =$L$4/(1+$L$5*EXP(-$L$6*C14)) -> 212899.17 | I14: =(G14-A14)^2 -> 1.8355375e+09
A15: 179008 | C15: 14 | E15: =A15 -> 179008 | G15: =$L$4/(1+$L$5*EXP(-$L$6*C15)) -> 215767.31 | I15: =(G15-A15)^2 -> 1.3512472e+09
A16: 173652 | C16: 15 | E16: =A16 -> 173652 | G16: =$L$4/(1+$L$5*EXP(-$L$6*C16)) -> 218524.44 | I16: =(G16-A16)^2 -> 2.0135359e+09
A17: 180841 | C17: 16 | E17: =A17 -> 180841 | G17: =$L$4/(1+$L$5*EXP(-$L$6*C17)) -> 221171.29 | I17: =(G17-A17)^2 -> 1.6265326e+09
A18: 178780 | C18: 17 | E18: =A18 -> 178780 | G18: =$L$4/(1+$L$5*EXP(-$L$6*C18)) -> 223709.01 | I18: =(G18-A18)^2 -> 2.0186162e+09
... A43: 269320 | C43: 42 | E43: =A43 -> 269320 | G43: =$L$4/(1+$L$5*EXP(-$L$6*C43)) -> 259062.45 | I43: =(G43-A43)^2 -> 1.0521738e+08

Sheet 04 Summary
A1: TIME | B1: Rests of Linear Model | C1: Rests of Power Model | D1: Rests of Exponential Model | E1: Rests of Quadratic Model | F1: Rests of Logistic Model | I1: Variance
A2: 1 | B2: =('03 Linear Trend'!J2-'03 Linear Trend'!A2)^2 -> 84680778 | C2: =('03 Power Trend'!J2-'03 Power Trend'!A2)^2 -> 7.5804298e+08 | D2: =('03 Exponential Trend'!J2-'03 Exponential Trend'!A2)^2 -> 12033837 | E2: =('04 Quadratic Trend'!K2-'04 Quadratic Trend'!A2)^2 -> 45650458 | F2: =('04 Logistic Trend'!G2-'04 Logistic Trend'!A2)^2 -> 3.7740663e+08 | H2: Rests of Linear Model | I2: =_xlfn.VAR.S(B2:B43) -> 1.8057538e+16 | J2: =I2/MIN($I$2:$I$6) -> 4.9970991
A3: 2 | B3: =('03 Linear Trend'!J3-'03 Linear Trend'!A3)^2 -> 2.3573376e+08 | C3: =('03 Power Trend'!J3-'03 Power Trend'!A3)^2 -> 4.7300715e+08 | D3: =('03 Exponential Trend'!J3-'03 Exponential Trend'!A3)^2 -> 1.0657064e+08 | E3: =('04 Quadratic Trend'!K3-'04 Quadratic Trend'!A3)^2 -> 3661774.5 | F3: =('04 Logistic Trend'!G3-'04 Logistic Trend'!A3)^2 -> 2.1458852e+08 | H3: Rests of Power Model | I3: =_xlfn.VAR.S(C2:C43) -> 1.5996921e+17 | J3: =I3/MIN($I$2:$I$6) -> 44.268604
A4: 3 | B4: =('03 Linear Trend'!J4-'03 Linear Trend'!A4)^2 -> 73411157 | C4: =('03 Power Trend'!J4-'03 Power Trend'!A4)^2 -> 69022860 | D4: =('03 Exponential Trend'!J4-'03 Exponential Trend'!A4)^2 -> 17755103 | E4: =('04 Quadratic Trend'!K4-'04 Quadratic Trend'!A4)^2 -> 6107204.6 | F4: =('04 Logistic Trend'!G4-'04 Logistic Trend'!A4)^2 -> 5.1665111e+08 | H4: Rests of Exponential Model | I4: =_xlfn.VAR.S(D2:D43) -> 1.0002611e+16 | J4: =I4/MIN($I$2:$I$6) -> 2.7680428
A5: 4 | B5: =('03 Linear Trend'!J5-'03 Linear Trend'!A5)^2 -> 1.4097855e+08 | C5: =('03 Power Trend'!J5-'03 Power Trend'!A5)^2 -> 53181072 | D5: =('03 Exponential Trend'!J5-'03 Exponential Trend'!A5)^2 -> 66712019 | E5: =('04 Quadratic Trend'!K5-'04 Quadratic Trend'!A5)^2 -> 9715258.3 | F5: =('04 Logistic Trend'!G5-'04 Logistic Trend'!A5)^2 -> 4.2585303e+08 | H5: Rests of Quadratic Model | I5: =_xlfn.VAR.S(E2:E43) -> 3.6136042e+15 | J5: =I5/MIN($I$2:$I$6) -> 1 | L5: Quadratic Model describes Netherlands GVA in the most appropriate way
A6: 5 | B6: =('03 Linear Trend'!J6-'03 Linear Trend'!A6)^2 -> 6379899.5 | C6: =('03 Power Trend'!J6-'03 Power Trend'!A6)^2 -> 25313641 | D6: =('03 Exponential Trend'!J6-'03 Exponential Trend'!A6)^2 -> 312343.96 | E6: =('04 Quadratic Trend'!K6-'04 Quadratic Trend'!A6)^2 -> 16530756 | F6: =('04 Logistic Trend'!G6-'04 Logistic Trend'!A6)^2 -> 9.6758785e+08 | H6: Rests of Logistic Model | I6: =_xlfn.VAR.S(F2:F43) -> 9.0153465e+17 | J6: =I6/MIN($I$2:$I$6) -> 249.48351
A7: 6 | B7: =('03 Linear Trend'!J7-'03 Linear Trend'!A7)^2 -> 80232397 | C7: =('03 Power Trend'!J7-'03 Power Trend'!A7)^2 -> 480116.88 | D7: =('03 Exponential Trend'!J7-'03 Exponential Trend'!A7)^2 -> 41801992 | E7: =('04 Quadratic Trend'!K7-'04 Quadratic Trend'!A7)^2 -> 19470349 | F7: =('04 Logistic Trend'!G7-'04 Logistic Trend'!A7)^2 -> 6.6062785e+08
A8: 7 | B8: =('03 Linear Trend'!J8-'03 Linear Trend'!A8)^2 -> 1792014.5 | C8: =('03 Power Trend'!J8-'03 Power Trend'!A8)^2 -> 95576345 | D8: =('03 Exponential Trend'!J8-'03 Exponential Trend'!A8)^2 -> 346528.23 | E8: =('04 Quadratic Trend'!K8-'04 Quadratic Trend'!A8)^2 -> 1630969.4 | F8: =('04 Logistic Trend'!G8-'04 Logistic Trend'!A8)^2 -> 1.173116e+09
A9: 8 | B9: =('03 Linear Trend'!J9-'03 Linear Trend'!A9)^2 -> 32856615 | C9: =('03 Power Trend'!J9-'03 Power Trend'!A9)^2 -> 40654128 | D9: =('03 Exponential Trend'!J9-'03 Exponential Trend'!A9)^2 -> 18839076 | E9: =('04 Quadratic Trend'!K9-'04 Quadratic Trend'!A9)^2 -> 24278769 | F9: =('04 Logistic Trend'!G9-'04 Logistic Trend'!A9)^2 -> 9.4155423e+08
A10: 9 | B10: =('03 Linear Trend'!J10-'03 Linear Trend'!A10)^2 -> 3095922.5 | C10: =('03 Power Trend'!J10-'03 Power Trend'!A10)^2 -> 2.1003468e+08 | D10: =('03 Exponential Trend'!J10-'03 Exponential Trend'!A10)^2 -> 6994664.8 | E10: =('04 Quadratic Trend'!K10-'04 Quadratic Trend'!A10)^2 -> 758900.01 | F10: =('04 Logistic Trend'!G10-'04 Logistic Trend'!A10)^2 -> 1.5131024e+09
